File: fss/fss_090_2.txt
""
"Test Method","Tensile_R_yu.msm"
"Sample I. D.","10-1-304TD1 Hyunjin.mss"
"Specimen Number","4"

"Extension (mm)","Extensometer_A (mm/mm)","Extensometer_T (mm)","Load (kN)"

0.00017,0.00000,0.00002,-0.006
0.00016,0.00000,0.00000,-0.014
0.00009,0.00000,-0.00003,-0.013
-0.00015,0.00000,0.00002,0.001
0.00007,0.00000,-0.00001,-0.005
-0.00017,0.00000,-0.00004,-0.017
-0.00020,0.00000,-0.00003,-0.005
0.00010,0.00000,0.00004,0.001
-0.00004,0.00000,0.00002,-0.011
0.00007,0.00000,0.00000,-0.006
0.00005,0.00000,0.00004,0.002
-0.00001,0.00000,0.00005,0.000
0.00010,0.00000,0.00006,0.009
0.00007,0.00000,0.00004,0.006
0.00033,0.00001,0.00003,0.023
0.00011,0.00000,0.00004,0.019
0.00041,0.00001,0.00008,0.010
0.00041,0.00001,0.00007,0.042
0.00052,0.00001,0.00006,0.044
0.00059,0.00001,0.00008,0.031
0.00058,0.00001,0.00015,0.047
0.00089,0.00002,0.00010,0.041
0.00114,0.00002,0.00011,0.062
0.00122,0.00002,0.00020,0.055
0.00138,0.00003,0.00015,0.088
0.00154,0.00003,0.00021,0.092
0.00147,0.00003,0.00021,0.100
0.00189,0.00004,0.00019,0.102
0.00222,0.00004,0.00026,0.121
0.00240,0.00005,0.00023,0.142
0.00253,0.00005,0.00030,0.152
0.00275,0.00005,0.00032,0.171
0.00279,0.00006,0.00035,0.180
0.00315,0.00006,0.00032,0.190
0.00345,0.00007,0.00037,0.206
0.00402,0.00008,0.00043,0.218
0.00430,0.00009,0.00044,0.246
0.00461,0.00009,0.00048,0.275
0.00501,0.00010,0.00052,0.278
0.00564,0.00011,0.00058,0.317
0.00594,0.00012,0.00064,0.342
0.00624,0.00012,0.00067,0.348
0.00699,0.00014,0.00075,0.380
0.00748,0.00015,0.00080,0.417
0.00792,0.00016,0.00085,0.443
0.00865,0.00017,0.00088,0.478
0.00932,0.00019,0.00090,0.508
0.01005,0.00020,0.00098,0.537
0.01043,0.00021,0.00102,0.571
0.01136,0.00023,0.00115,0.631
0.01216,0.00024,0.00119,0.663
0.01283,0.00026,0.00124,0.690
0.01369,0.00027,0.00136,0.730
0.01476,0.00030,0.00144,0.783
0.01558,0.00031,0.00149,0.830
0.01647,0.00033,0.00161,0.874
0.01745,0.00035,0.00168,0.905
0.01860,0.00037,0.00177,0.968
0.01965,0.00039,0.00182,1.030
0.02086,0.00042,0.00192,1.083
0.02172,0.00043,0.00206,1.144
0.02304,0.00046,0.00217,1.213
0.02435,0.00049,0.00225,1.270
0.02559,0.00051,0.00238,1.324
0.02692,0.00054,0.00247,1.377
0.02823,0.00056,0.00260,1.464
0.02949,0.00059,0.00269,1.530
0.03074,0.00061,0.00285,1.585
0.03223,0.00064,0.00294,1.670
0.03389,0.00068,0.00308,1.755
0.03558,0.00071,0.00319,1.821
0.03714,0.00074,0.00336,1.895
0.03875,0.00078,0.00349,1.977
0.04049,0.00081,0.00363,2.076
0.04211,0.00084,0.00383,2.149
0.04419,0.00088,0.00395,2.214
0.04598,0.00092,0.00413,2.317
0.04792,0.00096,0.00434,2.400
0.05021,0.00100,0.00450,2.511
0.05252,0.00105,0.00474,2.593
0.05472,0.00109,0.00497,2.679
0.05700,0.00114,0.00525,2.756
0.05955,0.00119,0.00549,2.845
0.06236,0.00125,0.00578,2.934
0.06507,0.00130,0.00609,3.014
0.06825,0.00137,0.00646,3.098
0.07165,0.00143,0.00690,3.183
0.07497,0.00150,0.00737,3.229
0.07892,0.00158,0.00785,3.288
0.08306,0.00166,0.00839,3.357
0.08724,0.00174,0.00897,3.403
0.09212,0.00184,0.00972,3.445
0.09694,0.00194,0.01039,3.470
0.10206,0.00204,0.01117,3.524
0.10764,0.00215,0.01203,3.546
0.11364,0.00227,0.01292,3.543
0.11945,0.00239,0.01383,3.563
0.12582,0.00252,0.01482,3.605
0.13215,0.00264,0.01587,3.595
0.13893,0.00278,0.01693,3.594
0.14570,0.00291,0.01806,3.615
0.15286,0.00306,0.01920,3.625
0.16034,0.00321,0.02041,3.632
0.16779,0.00336,0.02161,3.645
0.17577,0.00352,0.02287,3.647
0.18385,0.00368,0.02419,3.629
0.19208,0.00384,0.02548,3.643
0.20036,0.00401,0.02680,3.649
0.20876,0.00418,0.02818,3.658
0.21703,0.00434,0.02951,3.674
0.22575,0.00452,0.03098,3.663
0.23485,0.00470,0.03228,3.676
0.24378,0.00488,0.03375,3.664
0.25314,0.00506,0.03522,3.678
0.26223,0.00524,0.03675,3.687
0.27225,0.00544,0.03819,3.697
0.28195,0.00564,0.03975,3.705
0.29156,0.00583,0.04123,3.706
0.30159,0.00603,0.04276,3.712
0.31152,0.00623,0.04433,3.724
0.32182,0.00644,0.04591,3.727
0.33210,0.00664,0.04749,3.732
0.34228,0.00685,0.04910,3.749
0.35277,0.00706,0.05076,3.747
0.36345,0.00727,0.05243,3.756
0.37418,0.00748,0.05405,3.766
0.38488,0.00770,0.05576,3.774
0.39616,0.00792,0.05748,3.790
0.40678,0.00814,0.05921,3.806
0.41805,0.00836,0.06090,3.807
0.42954,0.00859,0.06264,3.815
0.44111,0.00882,0.06449,3.816
0.45257,0.00905,0.06626,3.829
0.46419,0.00928,0.06810,3.836
0.47605,0.00952,0.06995,3.843
0.48825,0.00977,0.07181,3.845
0.50062,0.01001,0.07369,3.849
0.51315,0.01026,0.07557,3.876
0.52583,0.01052,0.07754,3.886
0.53887,0.01078,0.07950,3.882
0.55167,0.01103,0.08153,3.910
0.56480,0.01130,0.08347,3.916
0.57811,0.01156,0.08561,3.923
0.59146,0.01183,0.08766,3.944
0.60515,0.01210,0.08974,3.959
0.61881,0.01238,0.09188,3.982
0.63286,0.01266,0.09398,3.975
0.64680,0.01294,0.09609,3.979
0.66052,0.01321,0.09828,4.006
0.67506,0.01350,0.10055,4.000
0.68934,0.01379,0.10268,4.016
0.70399,0.01408,0.10492,4.033
0.71859,0.01437,0.10715,4.054
0.73291,0.01466,0.10945,4.033
0.74788,0.01496,0.11179,4.061
0.76304,0.01526,0.11409,4.076
0.77799,0.01556,0.11644,4.080
0.79374,0.01587,0.11877,4.091
0.80890,0.01618,0.12120,4.112
0.82467,0.01649,0.12365,4.128
0.84044,0.01681,0.12605,4.134
0.85638,0.01713,0.12849,4.148
0.87213,0.01744,0.13088,4.178
0.88833,0.01777,0.13336,4.178
0.90483,0.01810,0.13587,4.176
0.92079,0.01842,0.13840,4.199
0.93726,0.01875,0.14086,4.210
0.95390,0.01908,0.14340,4.214
0.97059,0.01941,0.14597,4.223
0.98715,0.01974,0.14851,4.245
1.00389,0.02008,0.15107,4.246
1.02096,0.02042,0.15366,4.255
1.03800,0.02076,0.15625,4.274
1.05548,0.02111,0.15884,4.292
1.07235,0.02145,0.16151,4.294
1.08974,0.02179,0.16415,4.308
1.10702,0.02214,0.16672,4.325
1.12443,0.02249,0.16938,4.332
1.14164,0.02283,0.17211,4.338
1.15911,0.02318,0.17472,4.358
1.17635,0.02353,0.17735,4.368
1.19403,0.02388,0.18002,4.368
1.21179,0.02424,0.18260,4.384
1.22954,0.02459,0.18531,4.410
1.24726,0.02495,0.18802,4.415
1.26521,0.02530,0.19073,4.423
1.28381,0.02568,0.19350,4.439
1.30193,0.02604,0.19619,4.444
1.32030,0.02641,0.19900,4.459
1.33852,0.02677,0.20177,4.465
1.35683,0.02714,0.20456,4.489
1.37520,0.02750,0.20732,4.495
1.39324,0.02786,0.21012,4.501
1.41175,0.02823,0.21288,4.513
1.43033,0.02861,0.21566,4.532
1.44891,0.02898,0.21857,4.537
1.46718,0.02934,0.22135,4.539
1.48599,0.02972,0.22413,4.553
1.50455,0.03009,0.22691,4.567
1.52342,0.03047,0.22984,4.576
1.54242,0.03085,0.23260,4.593
1.56159,0.03123,0.23539,4.603
1.58060,0.03161,0.23827,4.611
1.59927,0.03199,0.24115,4.622
1.61905,0.03238,0.24390,4.634
1.63802,0.03276,0.24663,4.650
1.65719,0.03314,0.24966,4.644
1.67636,0.03353,0.25251,4.663
1.69550,0.03391,0.25534,4.677
1.71505,0.03430,0.25828,4.686
1.73426,0.03469,0.26126,4.692
1.75373,0.03507,0.26414,4.706
1.77348,0.03547,0.26700,4.718
1.79309,0.03586,0.27004,4.717
1.81242,0.03625,0.27311,4.735
1.83293,0.03666,0.27598,4.754
1.85322,0.03706,0.27885,4.757
1.87263,0.03745,0.28196,4.758
1.89242,0.03785,0.28492,4.789
1.91285,0.03826,0.28779,4.786
1.93317,0.03866,0.29074,4.791
1.95247,0.03905,0.29386,4.799
1.97297,0.03946,0.29677,4.820
1.99372,0.03987,0.29975,4.826
2.01395,0.04028,0.30285,4.835
2.03422,0.04068,0.30596,4.855
2.05455,0.04109,0.30896,4.856
2.07525,0.04151,0.31196,4.862
2.09608,0.04192,0.31505,4.870
2.11650,0.04233,0.31821,4.883
2.13721,0.04274,0.32117,4.887
2.15789,0.04316,0.32424,4.888
2.17827,0.04357,0.32737,4.915
2.19951,0.04399,0.33040,4.917
2.21992,0.04440,0.33349,4.921
2.24115,0.04482,0.33656,4.931
2.26181,0.04524,0.33976,4.955
2.28300,0.04566,0.34281,4.953
2.30410,0.04608,0.34592,4.961
2.32507,0.04650,0.34901,4.965
2.34649,0.04693,0.35210,4.980
2.36799,0.04736,0.35524,4.980
2.38928,0.04779,0.35838,4.997
2.41054,0.04821,0.36148,5.008
2.43202,0.04864,0.36466,5.012
2.45361,0.04907,0.36774,5.011
2.47484,0.04950,0.37099,5.027
2.49667,0.04993,0.37424,5.044
2.51850,0.05037,0.37731,5.050
2.53981,0.05080,0.38049,5.045
2.56170,0.05123,0.38370,5.067
2.58395,0.05168,0.38685,5.074
2.60638,0.05213,0.39002,5.073
2.62908,0.05258,0.39332,5.083
2.65135,0.05303,0.39661,5.096
2.67417,0.05348,0.39987,5.103
2.69730,0.05395,0.40321,5.113
2.72039,0.05441,0.40654,5.130
2.74298,0.05486,0.40997,5.135
2.76645,0.05533,0.41328,5.135
2.78989,0.05580,0.41673,5.139
2.81302,0.05626,0.42015,5.168
2.83725,0.05674,0.42359,5.159
2.86132,0.05723,0.42696,5.157
2.88521,0.05770,0.43044,5.180
2.90944,0.05819,0.43388,5.192
2.93294,0.05866,0.43729,5.192
2.95750,0.05915,0.44071,5.217
2.98176,0.05964,0.44420,5.219
3.00558,0.06011,0.44770,5.209
3.03019,0.06060,0.45105,5.213
3.05429,0.06109,0.45456,5.228
3.07887,0.06158,0.45807,5.256
3.10354,0.06207,0.46145,5.243
3.12816,0.06256,0.46496,5.245
3.15287,0.06306,0.46837,5.256
3.17737,0.06355,0.47189,5.265
3.20169,0.06403,0.47541,5.269
3.22660,0.06453,0.47898,5.285
3.25064,0.06501,0.48246,5.285
3.27585,0.06552,0.48590,5.289
3.30049,0.06601,0.48938,5.297
3.32546,0.06651,0.49289,5.320
3.35003,0.06700,0.49642,5.321
3.37543,0.06751,0.49988,5.294
3.40031,0.06801,0.50346,5.316
3.42546,0.06851,0.50697,5.333
3.45042,0.06901,0.51045,5.335
3.47577,0.06952,0.51393,5.351
3.50089,0.07002,0.51746,5.341
3.52584,0.07052,0.52099,5.359
3.55108,0.07102,0.52451,5.361
3.57615,0.07152,0.52805,5.366
3.60161,0.07203,0.53160,5.381
3.62725,0.07255,0.53517,5.365
3.65318,0.07306,0.53866,5.380
3.67868,0.07357,0.54225,5.419
3.70389,0.07408,0.54585,5.409
3.72946,0.07459,0.54935,5.402
3.75534,0.07511,0.55287,5.403
3.77997,0.07560,0.55645,5.420
3.80601,0.07612,0.56004,5.429
3.83161,0.07663,0.56359,5.420
3.85745,0.07715,0.56720,5.432
3.88325,0.07766,0.57084,5.448
3.90929,0.07819,0.57432,5.440
3.93530,0.07871,0.57792,5.445
3.96104,0.07922,0.58153,5.469
3.98705,0.07974,0.58510,5.470
4.01337,0.08027,0.58869,5.451
4.03905,0.08078,0.59227,5.463
4.06514,0.08130,0.59591,5.478
4.09122,0.08182,0.59955,5.480
4.11756,0.08235,0.60312,5.483
4.14379,0.08288,0.60677,5.493
4.17043,0.08341,0.61042,5.506
4.19672,0.08393,0.61404,5.495
4.22292,0.08446,0.61768,5.501
4.24936,0.08499,0.62132,5.519
4.27591,0.08552,0.62486,5.509
4.30209,0.08604,0.62854,5.517
4.32870,0.08657,0.63221,5.529
4.35493,0.08710,0.63589,5.532
4.38180,0.08764,0.63951,5.535
4.40854,0.08817,0.64323,5.540
4.43537,0.08871,0.64694,5.535
4.46185,0.08924,0.65053,5.546
4.48841,0.08977,0.65415,5.548
4.51526,0.09031,0.65782,5.558
4.54167,0.09083,0.66142,5.565
4.56854,0.09137,0.66492,5.563
4.59554,0.09191,0.66848,5.596
4.62232,0.09245,0.67210,5.569
4.64940,0.09299,0.67567,5.579
4.67634,0.09353,0.67937,5.574
4.70357,0.09407,0.68300,5.587
4.73037,0.09461,0.68671,5.595
4.75773,0.09515,0.69033,5.594
4.78472,0.09569,0.69404,5.598
4.81097,0.09622,0.69775,5.602
4.83833,0.09677,0.70149,5.604
4.86529,0.09731,0.70517,5.603
4.89259,0.09785,0.70888,5.616
4.91994,0.09840,0.71265,5.617
4.94734,0.09895,0.71638,5.621
4.97450,0.09949,0.72006,5.622
5.00198,0.10004,0.72382,5.624
5.02936,0.10059,0.72747,5.632
5.05631,0.10113,0.73120,5.617
5.08359,0.10167,0.73494,5.639
5.11129,0.10223,0.73859,5.638
5.13853,0.10277,0.74222,5.650
5.16594,0.10332,0.74589,5.646
5.19399,0.10388,0.74954,5.655
5.22153,0.10443,0.75326,5.649
5.24906,0.10498,0.75680,5.656
5.27665,0.10553,0.76060,5.654
5.30410,0.10608,0.76428,5.652
5.33129,0.10663,0.76788,5.658
5.35903,0.10718,0.77161,5.661
5.38651,0.10773,0.77542,5.661
5.41441,0.10829,0.77907,5.667
5.44233,0.10885,0.78286,5.665
5.47006,0.10940,0.78666,5.677
5.49820,0.10996,0.79035,5.691
5.52574,0.11051,0.79405,5.673
5.55385,0.11108,0.79774,5.703
5.58134,0.11163,0.80147,5.682
5.60948,0.11219,0.80514,5.692
5.63730,0.11275,0.80880,5.686
5.66533,0.11331,0.81254,5.695
5.69328,0.11387,0.81623,5.714
5.72175,0.11444,0.81991,5.700
5.74981,0.11500,0.82363,5.703
5.77786,0.11556,0.82741,5.712
5.80580,0.11612,0.83108,5.725
5.83372,0.11667,0.83481,5.711
5.86206,0.11724,0.83852,5.718
5.89016,0.11780,0.84222,5.723
5.91833,0.11837,0.84590,5.727
5.94670,0.11893,0.84961,5.722
5.97518,0.11950,0.85339,5.732
6.00350,0.12007,0.85703,5.728
6.03172,0.12063,0.86079,5.727
6.06006,0.12120,0.86451,5.735
6.08848,0.12177,0.86823,5.735
6.11652,0.12233,0.87189,5.739
6.14519,0.12290,0.87563,5.730
6.17344,0.12347,0.87939,5.743
6.20189,0.12404,0.88318,5.746
6.23086,0.12462,0.88691,5.755
6.25960,0.12519,0.89065,5.742
6.28785,0.12576,0.89439,5.752
6.31659,0.12633,0.89815,5.745
6.34539,0.12691,0.90188,5.751
6.37342,0.12747,0.90569,5.763
6.40195,0.12804,0.90937,5.769
6.43049,0.12861,0.91316,5.751
6.45948,0.12919,0.91684,5.756
6.48849,0.12977,0.92061,5.766
6.51700,0.13034,0.92435,5.765
6.54582,0.13092,0.92805,5.758
6.57453,0.13149,0.93185,5.765
6.60343,0.13207,0.93562,5.769
6.63215,0.13264,0.93934,5.771
6.66095,0.13322,0.94315,5.759
6.68981,0.13380,0.94685,5.775
6.71868,0.13437,0.95063,5.767
6.74790,0.13496,0.95441,5.765
6.77680,0.13554,0.95821,5.775
6.80582,0.13612,0.96195,5.782
6.83489,0.13670,0.96575,5.775
6.86415,0.13728,0.96951,5.767
6.89250,0.13785,0.97326,5.783
6.92153,0.13843,0.97707,5.786
6.95057,0.13901,0.98084,5.786
6.97976,0.13960,0.98472,5.789
7.00901,0.14018,0.98849,5.789
7.03824,0.14076,0.99223,5.789
7.06732,0.14135,0.99601,5.795
7.09637,0.14193,0.99971,5.789
7.12576,0.14252,1.00348,5.783
7.15481,0.14310,1.00726,5.788
7.18449,0.14369,1.01099,5.809
7.21331,0.14427,1.01479,5.804
7.24283,0.14486,1.01855,5.787
7.27188,0.14544,1.02232,5.782
7.30120,0.14602,1.02616,5.790
7.33057,0.14661,1.02989,5.804
7.36016,0.14720,1.03371,5.795
7.38903,0.14778,1.03753,5.791
7.41856,0.14837,1.04129,5.814
7.44791,0.14896,1.04500,5.792
7.47735,0.14955,1.04873,5.795
7.50683,0.15014,1.05258,5.812
7.53665,0.15073,1.05631,5.801
7.56589,0.15132,1.06003,5.810
7.59525,0.15191,1.06376,5.806
7.62458,0.15249,1.06756,5.798
7.65386,0.15308,1.07126,5.808
7.68336,0.15367,1.07491,5.796
7.71250,0.15425,1.07870,5.810
7.74232,0.15485,1.08252,5.806
7.77181,0.15544,1.08626,5.805
7.80157,0.15603,1.09000,5.797
7.83124,0.15662,1.09371,5.809
7.86055,0.15721,1.09745,5.809
7.89024,0.15780,1.10112,5.804
7.91882,0.15838,1.10479,5.809
7.94869,0.15897,1.10855,5.819
7.97786,0.15956,1.11217,5.801
8.00754,0.16015,1.11592,5.814
8.03728,0.16075,1.11965,5.812
8.06688,0.16134,1.12337,5.814
8.09647,0.16193,1.12705,5.816
8.12588,0.16252,1.13077,5.810
8.15561,0.16311,1.13449,5.821
8.18472,0.16369,1.13816,5.812
8.21419,0.16428,1.14186,5.810
8.24371,0.16487,1.14556,5.817
8.27340,0.16547,1.14923,5.811
8.30324,0.16606,1.15289,5.807
8.33278,0.16666,1.15662,5.810
8.36205,0.16724,1.16037,5.824
8.39186,0.16784,1.16402,5.820
8.42123,0.16842,1.16770,5.824
8.45016,0.16900,1.17145,5.818
8.47991,0.16960,1.17508,5.819
8.50908,0.17018,1.17882,5.817
8.53840,0.17077,1.18253,5.817
8.56813,0.17136,1.18620,5.827
8.59755,0.17195,1.18990,5.822
8.62661,0.17253,1.19358,5.821
8.65603,0.17312,1.19724,5.822
8.68505,0.17370,1.20085,5.821
8.71438,0.17429,1.20450,5.806
8.74357,0.17487,1.20812,5.816
8.77266,0.17545,1.21173,5.829
8.80194,0.17604,1.21523,5.824
8.83132,0.17663,1.21880,5.812
8.86030,0.17721,1.22247,5.827
8.88894,0.17778,1.22598,5.823
8.91799,0.17836,1.22949,5.806
8.94640,0.17893,1.23304,5.823
8.97525,0.17950,1.23667,5.815
9.00387,0.18008,1.24020,5.817
9.03250,0.18065,1.24377,5.800
9.06122,0.18122,1.24731,5.807
9.09024,0.18180,1.25080,5.821
9.11892,0.18238,1.25432,5.810
9.14698,0.18294,1.25784,5.809
9.17559,0.18351,1.26135,5.826
9.20356,0.18407,1.26477,5.815
9.23208,0.18464,1.26831,5.810
9.25991,0.18520,1.27188,5.808
9.28791,0.18576,1.27540,5.814
9.31557,0.18631,1.27879,5.814
9.34359,0.18687,1.28226,5.807
9.37135,0.18743,1.28575,5.817
9.39889,0.18798,1.28916,5.818
9.42663,0.18853,1.29257,5.817
9.45394,0.18908,1.29595,5.811
9.48046,0.18961,1.29928,5.808
9.50791,0.19016,1.30258,5.812
9.53474,0.19069,1.30594,5.812
9.56126,0.19123,1.30922,5.816
9.58793,0.19176,1.31241,5.814
9.61442,0.19229,1.31562,5.806
9.64073,0.19281,1.31885,5.805
9.66609,0.19332,1.32203,5.811
9.69204,0.19384,1.32520,5.799
9.71752,0.19435,1.32832,5.807
9.74249,0.19485,1.33146,5.804
9.76764,0.19535,1.33454,5.809
9.79243,0.19585,1.33758,5.800
9.81714,0.19634,1.34065,5.808
9.84175,0.19683,1.34367,5.806
9.86647,0.19733,1.34669,5.804
9.89100,0.19782,1.34964,5.796
9.91482,0.19830,1.35265,5.800
9.93909,0.19878,1.35562,5.795
9.96305,0.19926,1.35858,5.799
9.98632,0.19973,1.36150,5.797
10.01018,0.20020,1.36444,5.811
10.03378,0.20068,1.36730,5.799
10.05716,0.20114,1.37018,5.793
10.08091,0.20162,1.37314,5.796
10.10439,0.20209,1.37602,5.799
10.12790,0.20256,1.37881,5.789
10.15128,0.20303,1.38172,5.791
10.17460,0.20349,1.38455,5.802
10.19754,0.20395,1.38731,5.792
10.22047,0.20441,1.39007,5.787
10.24304,0.20486,1.39298,5.799
10.26590,0.20532,1.39571,5.797
10.28813,0.20576,1.39842,5.789
10.31043,0.20621,1.40118,5.787
10.33275,0.20666,1.40393,5.790
10.35519,0.20710,1.40663,5.785
10.37741,0.20755,1.40930,5.788
10.39947,0.20799,1.41202,5.793
10.42134,0.20843,1.41468,5.790
10.44293,0.20886,1.41725,5.778
10.46461,0.20929,1.41987,5.781
10.48612,0.20972,1.42252,5.780
10.50675,0.21013,1.42509,5.782
10.52807,0.21056,1.42762,5.775
10.54894,0.21098,1.43013,5.785
10.56939,0.21139,1.43270,5.783
10.59006,0.21180,1.43515,5.779
10.61066,0.21221,1.43759,5.783
10.63115,0.21262,1.44008,5.780
10.65138,0.21303,1.44244,5.783
10.67117,0.21342,1.44487,5.776
10.69090,0.21382,1.44733,5.776
10.71032,0.21421,1.44968,5.780
10.73012,0.21460,1.45200,5.771
10.74911,0.21498,1.45432,5.768
10.76779,0.21536,1.45663,5.776
10.78685,0.21574,1.45882,5.767
10.80596,0.21612,1.46109,5.766
10.82420,0.21648,1.46336,5.773
10.84281,0.21686,1.46564,5.779
10.86159,0.21723,1.46777,5.770
10.87996,0.21760,1.47002,5.765
10.89834,0.21797,1.47223,5.770
10.91657,0.21833,1.47443,5.768
10.93505,0.21870,1.47660,5.764
10.95283,0.21906,1.47873,5.757
10.97056,0.21941,1.48084,5.768
10.98847,0.21977,1.48295,5.762
11.00640,0.22013,1.48499,5.759
11.02329,0.22047,1.48713,5.760
11.04080,0.22082,1.48928,5.767
11.05833,0.22117,1.49131,5.751
11.07576,0.22152,1.49338,5.758
11.09265,0.22185,1.49541,5.764
11.10966,0.22219,1.49749,5.757
11.12657,0.22253,1.49945,5.752
11.14372,0.22287,1.50146,5.754
11.15996,0.22320,1.50340,5.753
11.17634,0.22353,1.50528,5.741
11.19284,0.22386,1.50716,5.750
11.20845,0.22417,1.50910,5.754
11.22450,0.22449,1.51093,5.751
11.24071,0.22481,1.51280,5.739
11.25671,0.22513,1.51468,5.756
11.27224,0.22544,1.51651,5.743
11.28772,0.22575,1.51825,5.740
11.30340,0.22607,1.52006,5.744
11.31884,0.22638,1.52192,5.755
11.33440,0.22669,1.52364,5.746
11.34948,0.22699,1.52535,5.732
11.36441,0.22729,1.52712,5.749
11.37941,0.22759,1.52883,5.745
11.39436,0.22789,1.53047,5.739
11.40950,0.22819,1.53215,5.745
11.42400,0.22848,1.53385,5.736
11.43897,0.22878,1.53550,5.742
11.45373,0.22907,1.53706,5.738
11.46743,0.22935,1.53870,5.740
11.48194,0.22964,1.54032,5.741
11.49654,0.22993,1.54186,5.736
11.51059,0.23021,1.54342,5.726
11.52476,0.23050,1.54505,5.738
11.53831,0.23077,1.54653,5.735
11.55225,0.23104,1.54807,5.728
11.56600,0.23132,1.54957,5.731
11.57972,0.23159,1.55108,5.739
11.59360,0.23187,1.55252,5.726
11.60678,0.23214,1.55399,5.725
11.62024,0.23240,1.55550,5.726
11.63333,0.23267,1.55685,5.722
11.64673,0.23293,1.55828,5.716
11.65967,0.23319,1.55976,5.732
11.67281,0.23346,1.56115,5.721
11.68566,0.23371,1.56258,5.727
11.69858,0.23397,1.56396,5.714
11.71107,0.23422,1.56536,5.715
11.72357,0.23447,1.56663,5.727
11.73620,0.23472,1.56801,5.714
11.74846,0.23497,1.56929,5.720
11.76096,0.23522,1.57062,5.718
11.77349,0.23547,1.57190,5.712
11.78581,0.23572,1.57316,5.709
11.79734,0.23595,1.57451,5.714
11.80981,0.23620,1.57582,5.709
11.82185,0.23644,1.57705,5.707
11.83396,0.23668,1.57836,5.705
11.84598,0.23692,1.57963,5.711
11.85798,0.23716,1.58083,5.701
11.86971,0.23739,1.58209,5.700
11.88153,0.23763,1.58332,5.709
11.89341,0.23787,1.58451,5.707
11.90520,0.23810,1.58565,5.700
11.91682,0.23834,1.58688,5.707
11.92836,0.23857,1.58806,5.701
11.93977,0.23880,1.58916,5.703
11.95133,0.23903,1.59028,5.700
11.96252,0.23925,1.59150,5.699
11.97398,0.23948,1.59264,5.699
11.98550,0.23971,1.59362,5.693
11.99648,0.23993,1.59485,5.696
12.00731,0.24015,1.59599,5.698
12.01878,0.24038,1.59696,5.692
12.02988,0.24060,1.59807,5.687
12.04077,0.24082,1.59923,5.697
12.05165,0.24103,1.60026,5.696
12.06235,0.24125,1.60130,5.692
12.07325,0.24146,1.60233,5.693
12.08394,0.24168,1.60336,5.696
12.09498,0.24190,1.60437,5.686
12.10583,0.24212,1.60541,5.690
12.11617,0.24232,1.60640,5.691
12.12695,0.24254,1.60739,5.691
12.13773,0.24275,1.60832,5.681
12.14828,0.24297,1.60931,5.680
12.15876,0.24318,1.61036,5.689
12.16941,0.24339,1.61121,5.685
12.18016,0.24360,1.61215,5.674
12.19055,0.24381,1.61315,5.682
12.20080,0.24402,1.61408,5.687
12.21129,0.24423,1.61494,5.683
12.22198,0.24444,1.61580,5.675
12.23199,0.24464,1.61673,5.678
12.24237,0.24485,1.61760,5.684
12.25259,0.24505,1.61843,5.669
12.26247,0.24525,1.61934,5.675
12.27302,0.24546,1.62018,5.677
12.28322,0.24566,1.62097,5.668
12.29379,0.24588,1.62181,5.665
12.30371,0.24607,1.62271,5.671
12.31355,0.24627,1.62346,5.667
12.32354,0.24647,1.62425,5.667
12.33389,0.24668,1.62507,5.661
12.34370,0.24687,1.62587,5.666
12.35421,0.24708,1.62661,5.668
12.36412,0.24728,1.62732,5.658
12.37386,0.24748,1.62818,5.664
12.38348,0.24767,1.62888,5.673
12.39368,0.24787,1.62963,5.664
12.40378,0.24808,1.63036,5.662
12.41336,0.24827,1.63114,5.661
12.42323,0.24846,1.63184,5.663
12.43363,0.24867,1.63255,5.653
12.44367,0.24887,1.63324,5.655
12.45301,0.24906,1.63403,5.659
12.46322,0.24926,1.63465,5.656
12.47336,0.24947,1.63536,5.657
12.48277,0.24966,1.63608,5.652
12.49255,0.24985,1.63673,5.652
12.50272,0.25005,1.63745,5.646
12.51197,0.25024,1.63811,5.649
12.52160,0.25043,1.63878,5.648
12.53163,0.25063,1.63945,5.653
12.54162,0.25083,1.64010,5.644
12.55114,0.25102,1.64081,5.648
12.56087,0.25122,1.64147,5.651
12.57077,0.25142,1.64205,5.644
12.58076,0.25162,1.64273,5.639
12.58999,0.25180,1.64335,5.653
12.59970,0.25199,1.64397,5.639
12.61030,0.25221,1.64456,5.637
12.61975,0.25239,1.64526,5.644
12.62930,0.25259,1.64587,5.643
12.63930,0.25279,1.64638,5.640
12.64901,0.25298,1.64702,5.630
12.65850,0.25317,1.64770,5.639
12.66828,0.25337,1.64821,5.636
12.67829,0.25357,1.64872,5.623
12.68812,0.25376,1.64938,5.627
12.69772,0.25395,1.64998,5.633
12.70782,0.25416,1.65050,5.631
12.71777,0.25436,1.65107,5.628
12.72729,0.25455,1.65167,5.627
12.73708,0.25474,1.65223,5.632
12.74724,0.25494,1.65267,5.626
12.75676,0.25514,1.65327,5.618
12.76628,0.25533,1.65386,5.625
12.77621,0.25552,1.65431,5.618
12.78625,0.25573,1.65485,5.615
12.79593,0.25592,1.65539,5.614
12.80531,0.25611,1.65596,5.615
12.81570,0.25631,1.65637,5.611
12.82543,0.25651,1.65693,5.612
12.83444,0.25669,1.65746,5.618
12.84451,0.25689,1.65790,5.612
12.85459,0.25709,1.65833,5.603
12.86411,0.25728,1.65890,5.609
12.87373,0.25747,1.65939,5.614
12.88382,0.25768,1.65984,5.605
12.89374,0.25787,1.66027,5.602
12.90316,0.25806,1.66081,5.598
12.91270,0.25825,1.66126,5.600
12.92300,0.25846,1.66162,5.595
12.93277,0.25866,1.66214,5.601
12.94236,0.25885,1.66264,5.599
12.95258,0.25905,1.66303,5.594
12.96281,0.25926,1.66341,5.591
12.97234,0.25945,1.66391,5.595
12.98214,0.25964,1.66431,5.594
12.99243,0.25985,1.66466,5.584
13.00234,0.26005,1.66507,5.586
13.01203,0.26024,1.66557,5.588
13.02179,0.26044,1.66592,5.583
13.03222,0.26064,1.66621,5.577
13.04150,0.26083,1.66674,5.579
13.05144,0.26103,1.66709,5.582
13.06175,0.26124,1.66741,5.578
13.07173,0.26143,1.66774,5.569
13.08110,0.26162,1.66826,5.578
13.09051,0.26181,1.66855,5.574
13.10080,0.26202,1.66880,5.569
13.11058,0.26221,1.66926,5.575
13.12005,0.26240,1.66969,5.573
13.13046,0.26261,1.66994,5.566
13.14025,0.26281,1.67016,5.565
13.15000,0.26300,1.67064,5.560
13.15927,0.26319,1.67092,5.566
13.16998,0.26340,1.67112,5.558
13.17973,0.26359,1.67150,5.553
13.18924,0.26378,1.67190,5.558
13.19925,0.26398,1.67210,5.556
13.20975,0.26420,1.67231,5.545
13.21958,0.26439,1.67275,5.550
13.22918,0.26458,1.67310,5.546
13.23944,0.26479,1.67322,5.544
13.24955,0.26499,1.67345,5.546
13.25928,0.26519,1.67400,5.544
13.26917,0.26538,1.67418,5.545
13.27959,0.26559,1.67424,5.533
13.28922,0.26578,1.67466,5.538
13.29864,0.26597,1.67515,5.543
13.30915,0.26618,1.67509,5.533
13.31947,0.26639,1.67528,5.531
13.32903,0.26658,1.67582,5.524
13.33900,0.26678,1.67604,5.541
13.34919,0.26698,1.67600,5.525
13.35908,0.26718,1.67638,5.519
13.36844,0.26737,1.67691,5.522
13.37892,0.26758,1.67679,5.521
13.38926,0.26779,1.67694,5.517
13.39869,0.26797,1.67752,5.512
13.40871,0.26817,1.67783,5.509
13.41942,0.26839,1.67757,5.518
13.42903,0.26858,1.67804,5.508
13.43874,0.26877,1.67863,5.499
13.44951,0.26899,1.67840,5.507
13.45975,0.26919,1.67854,5.499
13.46912,0.26938,1.67925,5.499
13.47923,0.26958,1.67939,5.497
13.49058,0.26981,1.67900,5.496
13.50021,0.27000,1.67965,5.491
13.50996,0.27020,1.68016,5.488
13.52084,0.27042,1.67978,5.485
13.53144,0.27063,1.67995,5.490
13.54031,0.27081,1.68066,5.477
13.55069,0.27101,1.68060,5.487
13.56189,0.27124,1.68029,5.482
13.57105,0.27142,1.68101,5.472
13.58139,0.27163,1.68120,5.472
13.59232,0.27185,1.68094,5.458
13.60221,0.27204,1.68120,5.465
13.61135,0.27223,1.68162,5.464
13.62213,0.27244,1.68158,5.455
13.63267,0.27265,1.68157,5.460
13.64254,0.27285,1.68194,5.456
13.65262,0.27305,1.68207,5.453
13.66318,0.27326,1.68206,5.450
13.67342,0.27347,1.68213,5.450
13.68358,0.27367,1.68239,5.445
13.69367,0.27387,1.68253,5.446
13.70434,0.27409,1.68250,5.446
13.71477,0.27430,1.68262,5.445
13.72461,0.27449,1.68290,5.433
13.73515,0.27470,1.68288,5.433
13.74611,0.27492,1.68284,5.434
13.75582,0.27512,1.68311,5.422
13.76641,0.27533,1.68323,5.424
13.77700,0.27554,1.68320,5.426
13.78767,0.27575,1.68329,5.421
13.79774,0.27595,1.68351,5.415
13.80793,0.27616,1.68351,5.411
13.81853,0.27637,1.68354,5.407
13.82892,0.27658,1.68363,5.404
13.83914,0.27678,1.68383,5.400
13.84980,0.27700,1.68384,5.400
13.86058,0.27721,1.68384,5.405
13.87034,0.27741,1.68397,5.391
13.88101,0.27762,1.68409,5.389
13.89167,0.27783,1.68404,5.388
13.90233,0.27805,1.68410,5.381
13.91267,0.27825,1.68426,5.378
13.92329,0.27847,1.68425,5.377
13.93385,0.27868,1.68425,5.374
13.94440,0.27889,1.68439,5.377
13.95483,0.27910,1.68449,5.364
13.96564,0.27931,1.68445,5.367
13.97625,0.27952,1.68449,5.367
13.98688,0.27974,1.68460,5.359
13.99779,0.27996,1.68464,5.353
14.00835,0.28017,1.68458,5.355
14.01906,0.28038,1.68469,5.350
14.02947,0.28059,1.68479,5.338
14.04025,0.28080,1.68475,5.340
14.05106,0.28102,1.68477,5.342
14.06163,0.28123,1.68481,5.328
14.07246,0.28145,1.68491,5.322
14.08312,0.28166,1.68489,5.316
14.09378,0.28188,1.68488,5.317
14.10472,0.28209,1.68495,5.313
14.11518,0.28230,1.68500,5.310
14.12594,0.28252,1.68496,5.314
14.13629,0.28273,1.68500,5.309
14.14696,0.28294,1.68508,5.305
14.15785,0.28316,1.68504,5.297
14.16881,0.28338,1.68505,5.301
14.17971,0.28359,1.68508,5.284
14.19034,0.28381,1.68515,5.285
14.20116,0.28402,1.68511,5.284
14.21186,0.28424,1.68511,5.274
14.22278,0.28446,1.68515,5.267
14.23398,0.28468,1.68515,5.269
14.24450,0.28489,1.68512,5.264
14.25563,0.28511,1.68511,5.260
14.26683,0.28534,1.68519,5.251
14.27766,0.28555,1.68515,5.255
14.28865,0.28577,1.68515,5.242
14.29980,0.28600,1.68520,5.229
14.31089,0.28622,1.68519,5.225
14.32169,0.28643,1.68519,5.230
14.33262,0.28665,1.68516,5.220
14.34385,0.28688,1.68521,5.214
14.35488,0.28710,1.68516,5.205
14.36617,0.28732,1.68514,5.209
14.37720,0.28754,1.68517,5.198
14.38768,0.28775,1.68519,5.192
14.39909,0.28798,1.68520,5.191
14.41062,0.28821,1.68513,5.190
14.42191,0.28844,1.68512,5.173
14.43288,0.28866,1.68516,5.164
14.44450,0.28889,1.68513,5.166
14.45560,0.28911,1.68515,5.159
14.46664,0.28933,1.68514,5.155
14.47818,0.28956,1.68512,5.143
14.48971,0.28979,1.68509,5.138
14.50126,0.29003,1.68511,5.125
14.51268,0.29025,1.68506,5.122
14.52449,0.29049,1.68508,5.121
14.53577,0.29072,1.68501,5.111
14.54736,0.29095,1.68505,5.104
14.55861,0.29117,1.68503,5.087
14.57063,0.29141,1.68502,5.088
14.58213,0.29164,1.68503,5.077
14.59370,0.29187,1.68498,5.069
14.60553,0.29211,1.68499,5.053
14.61741,0.29235,1.68495,5.058
14.62925,0.29258,1.68491,5.045
14.64094,0.29282,1.68489,5.030
14.65232,0.29305,1.68490,5.028
14.66417,0.29328,1.68484,5.013
14.67605,0.29352,1.68483,4.998
14.68823,0.29376,1.68481,4.991
14.70043,0.29401,1.68475,4.983
14.71229,0.29425,1.68476,4.968
14.72431,0.29449,1.68476,4.951
14.73629,0.29473,1.68469,4.940
14.74858,0.29497,1.68465,4.940
14.76097,0.29522,1.68464,4.920
14.77318,0.29546,1.68457,4.896
14.78558,0.29571,1.68456,4.889
14.79810,0.29596,1.68450,4.874
14.81064,0.29621,1.68452,4.850
14.82309,0.29646,1.68445,4.839
14.83567,0.29671,1.68437,4.826
14.84795,0.29696,1.68436,4.809
14.86078,0.29722,1.68430,4.783
14.87337,0.29747,1.68428,4.769
14.88655,0.29773,1.68415,4.748
14.89954,0.29799,1.68412,4.713
14.91237,0.29825,1.68404,4.678
14.92591,0.29852,1.68393,4.646
14.93986,0.29880,1.68379,4.577
14.95520,0.29910,1.68354,4.477
14.97450,0.29949,1.68301,4.257
14.99298,0.29986,1.68248,4.090
14.99985,0.30018,1.68222,3.992
14.99956,0.30050,1.68193,3.883
14.99936,0.30082,1.68172,3.803
14.99907,0.30114,1.68144,3.718
14.99878,0.30147,1.68115,3.628
14.99854,0.30178,1.68091,3.542
14.99837,0.30208,1.68074,3.487
14.99818,0.30238,1.68055,3.422
14.99802,0.30269,1.68039,3.347
14.99780,0.30300,1.68017,3.295
14.99761,0.30329,1.67998,3.229
14.99745,0.30359,1.67982,3.171
14.99730,0.30390,1.67966,3.103
14.99715,0.30419,1.67952,3.066
14.99702,0.30450,1.67939,3.016