File: fss/fss_090_1.txt
""
"Test Method","Tensile_R_yu.msm"
"Sample I. D.","10-1-304TD1 Hyunjin.mss"
"Specimen Number","3"

"Extension (mm)","Extensometer_A (mm/mm)","Extensometer_T (mm)","Load (kN)"

0.00039,0.00001,-0.00001,0.002
0.00004,0.00000,-0.00001,0.002
0.00020,0.00000,-0.00001,0.004
0.00033,0.00001,-0.00001,0.018
0.00041,0.00001,0.00007,0.036
0.00094,0.00002,0.00014,0.065
0.00143,0.00003,0.00020,0.109
0.00238,0.00005,0.00031,0.177
0.00351,0.00007,0.00049,0.249
0.00507,0.00010,0.00070,0.353
0.00753,0.00015,0.00097,0.480
0.01049,0.00021,0.00130,0.636
0.01414,0.00028,0.00166,0.835
0.01879,0.00038,0.00214,1.086
0.02431,0.00049,0.00264,1.355
0.03111,0.00062,0.00329,1.704
0.03926,0.00079,0.00402,2.088
0.04838,0.00097,0.00490,2.501
0.05958,0.00119,0.00610,2.910
0.07408,0.00148,0.00792,3.249
0.09322,0.00186,0.01077,3.447
0.11725,0.00235,0.01472,3.546
0.14585,0.00292,0.01945,3.607
0.17720,0.00354,0.02499,3.616
0.21135,0.00423,0.03106,3.629
0.24682,0.00494,0.03723,3.659
0.28349,0.00567,0.04360,3.669
0.32112,0.00642,0.04970,3.697
0.35953,0.00719,0.05587,3.720
0.39814,0.00796,0.06197,3.758
0.43663,0.00873,0.06811,3.782
0.47597,0.00952,0.07433,3.807
0.51473,0.01029,0.08053,3.839
0.55436,0.01109,0.08680,3.866
0.59397,0.01188,0.09317,3.888
0.63360,0.01267,0.09954,3.935
0.67332,0.01347,0.10600,3.966
0.71284,0.01426,0.11241,3.983
0.75341,0.01507,0.11882,4.024
0.79349,0.01587,0.12530,4.059
0.83430,0.01669,0.13171,4.071
0.87476,0.01750,0.13807,4.106
0.91549,0.01831,0.14432,4.142
0.95525,0.01910,0.15051,4.161
0.99554,0.01991,0.15669,4.196
1.03545,0.02071,0.16273,4.231
1.07543,0.02151,0.16890,4.240
1.11529,0.02231,0.17513,4.282
1.15468,0.02309,0.18130,4.293
1.19398,0.02388,0.18729,4.314
1.23252,0.02465,0.19333,4.350
1.27137,0.02543,0.19924,4.369
1.31000,0.02620,0.20519,4.403
1.34877,0.02698,0.21108,4.415
1.38739,0.02775,0.21704,4.442
1.42578,0.02852,0.22287,4.458
1.46361,0.02927,0.22878,4.482
1.50194,0.03004,0.23455,4.502
1.53986,0.03080,0.24030,4.522
1.57793,0.03156,0.24610,4.557
1.61578,0.03232,0.25175,4.567
1.65347,0.03307,0.25756,4.578
1.69102,0.03382,0.26314,4.607
1.72736,0.03455,0.26883,4.625
1.76456,0.03529,0.27447,4.642
1.80109,0.03602,0.28015,4.680
1.83745,0.03675,0.28575,4.672
1.87441,0.03749,0.29123,4.697
1.91015,0.03820,0.29673,4.710
1.94656,0.03893,0.30213,4.738
1.98193,0.03964,0.30757,4.744
2.01739,0.04035,0.31282,4.762
2.05225,0.04104,0.31815,4.783
2.08709,0.04174,0.32335,4.794
2.12192,0.04244,0.32861,4.808
2.15646,0.04313,0.33373,4.826
2.19060,0.04381,0.33879,4.834
2.22467,0.04449,0.34397,4.847
2.25802,0.04516,0.34896,4.863
2.29112,0.04582,0.35381,4.870
2.32424,0.04648,0.35869,4.887
2.35690,0.04714,0.36348,4.904
2.38945,0.04779,0.36831,4.924
2.42171,0.04843,0.37307,4.923
2.45298,0.04906,0.37776,4.936
2.48481,0.04970,0.38247,4.950
2.51555,0.05031,0.38713,4.957
2.54696,0.05094,0.39167,4.972
2.57714,0.05154,0.39624,4.972
2.60781,0.05216,0.40075,4.988
2.63843,0.05277,0.40516,5.014
2.66829,0.05337,0.40960,5.011
2.69727,0.05395,0.41389,5.019
2.72671,0.05453,0.41819,5.032
2.75466,0.05509,0.42242,5.036
2.78285,0.05566,0.42660,5.042
2.81045,0.05621,0.43060,5.057
2.83778,0.05676,0.43464,5.065
2.86489,0.05730,0.43863,5.069
2.89172,0.05783,0.44247,5.084
2.91849,0.05837,0.44632,5.096
2.94424,0.05888,0.45017,5.091
2.97000,0.05940,0.45385,5.103
2.99554,0.05991,0.45755,5.119
3.02012,0.06040,0.46124,5.120
3.04449,0.06089,0.46481,5.115
3.06941,0.06139,0.46825,5.137
3.09303,0.06186,0.47174,5.135
3.11705,0.06234,0.47519,5.139
3.14103,0.06282,0.47864,5.161
3.16405,0.06328,0.48199,5.147
3.18666,0.06373,0.48531,5.153
3.20934,0.06419,0.48857,5.168
3.23180,0.06464,0.49180,5.168
3.25416,0.06508,0.49494,5.187
3.27544,0.06551,0.49804,5.185
3.29678,0.06594,0.50117,5.176
3.31839,0.06637,0.50414,5.199
3.33909,0.06678,0.50719,5.201
3.36009,0.06720,0.51025,5.199
3.38118,0.06762,0.51321,5.211
3.40229,0.06805,0.51621,5.211
3.42307,0.06846,0.51918,5.213
3.44388,0.06888,0.52217,5.234
3.46417,0.06928,0.52517,5.229
3.48503,0.06970,0.52805,5.233
3.50499,0.07010,0.53098,5.233
3.52532,0.07051,0.53392,5.236
3.54566,0.07091,0.53682,5.259
3.56600,0.07132,0.53980,5.245
3.58627,0.07173,0.54259,5.259
3.60592,0.07212,0.54547,5.262
3.62594,0.07252,0.54839,5.264
3.64620,0.07292,0.55118,5.270
3.66604,0.07332,0.55406,5.273
3.68658,0.07373,0.55695,5.281
3.70626,0.07413,0.55976,5.280
3.72613,0.07452,0.56274,5.287
3.74617,0.07492,0.56558,5.287
3.76591,0.07532,0.56844,5.304
3.78553,0.07571,0.57139,5.303
3.80579,0.07612,0.57428,5.303
3.82583,0.07652,0.57720,5.320
3.84571,0.07691,0.58016,5.306
3.86636,0.07733,0.58308,5.316
3.88654,0.07773,0.58603,5.324
3.90684,0.07814,0.58896,5.318
3.92774,0.07855,0.59185,5.329
3.94829,0.07897,0.59479,5.339
3.96871,0.07937,0.59780,5.340
3.98941,0.07979,0.60068,5.347
4.01010,0.08020,0.60366,5.346
4.03059,0.08061,0.60663,5.353
4.05125,0.08103,0.60955,5.363
4.07197,0.08144,0.61252,5.361
4.09274,0.08185,0.61559,5.359
4.11367,0.08227,0.61852,5.375
4.13478,0.08270,0.62148,5.377
4.15558,0.08311,0.62460,5.375
4.17706,0.08354,0.62765,5.379
4.19882,0.08398,0.63055,5.392
4.21994,0.08440,0.63365,5.383
4.24131,0.08483,0.63670,5.393
4.26314,0.08526,0.63972,5.405
4.28443,0.08569,0.64280,5.403
4.30558,0.08611,0.64595,5.395
4.32812,0.08656,0.64900,5.411
4.34983,0.08700,0.65216,5.414
4.37147,0.08743,0.65533,5.420
4.39431,0.08789,0.65839,5.422
4.41641,0.08833,0.66169,5.423
4.43929,0.08879,0.66489,5.439
4.46262,0.08925,0.66801,5.439
4.48482,0.08970,0.67128,5.447
4.50776,0.09016,0.67452,5.444
4.53134,0.09063,0.67770,5.442
4.55395,0.09108,0.68105,5.436
4.57750,0.09155,0.68437,5.447
4.60143,0.09203,0.68760,5.454
4.62470,0.09249,0.69103,5.454
4.64973,0.09299,0.69430,5.467
4.67352,0.09347,0.69762,5.478
4.69749,0.09395,0.70109,5.464
4.72288,0.09446,0.70434,5.488
4.74735,0.09495,0.70778,5.483
4.77186,0.09544,0.71129,5.484
4.79769,0.09595,0.71467,5.499
4.82198,0.09644,0.71817,5.497
4.84799,0.09696,0.72185,5.500
4.87434,0.09749,0.72531,5.510
4.90009,0.09800,0.72892,5.513
4.92675,0.09854,0.73271,5.512
4.95409,0.09908,0.73638,5.535
4.98127,0.09963,0.74011,5.521
5.00858,0.10017,0.74405,5.519
5.03633,0.10073,0.74781,5.542
5.06442,0.10129,0.75166,5.531
5.09247,0.10185,0.75577,5.539
5.12182,0.10244,0.75972,5.548
5.15063,0.10301,0.76370,5.551
5.17981,0.10360,0.76791,5.549
5.21004,0.10420,0.77205,5.554
5.24022,0.10480,0.77615,5.562
5.26998,0.10540,0.78064,5.564
5.30076,0.10602,0.78494,5.569
5.33155,0.10663,0.78923,5.577
5.36200,0.10724,0.79374,5.570
5.39360,0.10787,0.79801,5.577
5.42463,0.10849,0.80233,5.576
5.45594,0.10912,0.80695,5.579
5.48886,0.10978,0.81121,5.593
5.52050,0.11041,0.81570,5.592
5.55209,0.11104,0.82041,5.592
5.58486,0.11170,0.82460,5.603
5.61646,0.11233,0.82926,5.611
5.64906,0.11298,0.83385,5.610
5.68190,0.11364,0.83819,5.618
5.71400,0.11428,0.84297,5.603
5.74765,0.11495,0.84736,5.618
5.78024,0.11560,0.85187,5.621
5.81286,0.11626,0.85661,5.616
5.84645,0.11693,0.86090,5.628
5.87831,0.11757,0.86537,5.622
5.91146,0.11823,0.87002,5.624
5.94502,0.11890,0.87427,5.631
5.97780,0.11956,0.87885,5.623
6.01147,0.12023,0.88343,5.640
6.04487,0.12090,0.88777,5.638
6.07739,0.12155,0.89249,5.634
6.11056,0.12221,0.89694,5.637
6.14369,0.12287,0.90117,5.640
6.17617,0.12352,0.90599,5.643
6.20977,0.12420,0.91020,5.651
6.24258,0.12485,0.91465,5.643
6.27549,0.12551,0.91932,5.651
6.30869,0.12617,0.92354,5.655
6.34134,0.12683,0.92807,5.652
6.37390,0.12748,0.93257,5.664
6.40671,0.12813,0.93675,5.657
6.43919,0.12878,0.94151,5.665
6.47276,0.12946,0.94569,5.666
6.50558,0.13011,0.95005,5.664
6.53789,0.13076,0.95464,5.666
6.57118,0.13142,0.95871,5.672
6.60355,0.13207,0.96325,5.664
6.63590,0.13272,0.96758,5.678
6.66924,0.13338,0.97173,5.678
6.70069,0.13401,0.97635,5.671
6.73412,0.13468,0.98039,5.686
6.76631,0.13533,0.98485,5.675
6.79864,0.13597,0.98928,5.681
6.83114,0.13662,0.99330,5.684
6.86293,0.13726,0.99778,5.692
6.89478,0.13790,1.00186,5.686
6.92651,0.13853,1.00587,5.686
6.95718,0.13914,1.01041,5.681
6.98908,0.13978,1.01419,5.701
7.02029,0.14041,1.01830,5.693
7.05112,0.14102,1.02258,5.692
7.08244,0.14165,1.02641,5.696
7.11290,0.14226,1.03053,5.693
7.14345,0.14287,1.03471,5.695
7.17398,0.14348,1.03846,5.694
7.20415,0.14408,1.04254,5.693
7.23349,0.14467,1.04663,5.691
7.26411,0.14528,1.05038,5.697
7.29438,0.14589,1.05435,5.703
7.32360,0.14647,1.05839,5.697
7.35330,0.14707,1.06217,5.706
7.38307,0.14766,1.06578,5.707
7.41110,0.14822,1.06989,5.701
7.43992,0.14880,1.07363,5.711
7.46890,0.14938,1.07723,5.713
7.49699,0.14994,1.08097,5.709
7.52509,0.15050,1.08479,5.700
7.55343,0.15107,1.08841,5.709
7.58140,0.15163,1.09203,5.712
7.60851,0.15217,1.09570,5.716
7.63617,0.15272,1.09944,5.708
7.66329,0.15327,1.10291,5.721
7.69003,0.15380,1.10639,5.716
7.71705,0.15434,1.10996,5.718
7.74345,0.15487,1.11356,5.706
7.77020,0.15540,1.11705,5.710
7.79691,0.15594,1.12049,5.716
7.82281,0.15646,1.12380,5.726
7.84801,0.15696,1.12726,5.725
7.87317,0.15746,1.13070,5.716
7.89855,0.15797,1.13401,5.727
7.92334,0.15847,1.13724,5.724
7.94760,0.15895,1.14038,5.725
7.97162,0.15943,1.14365,5.719
7.99567,0.15991,1.14691,5.717
8.02079,0.16042,1.15004,5.724
8.04474,0.16089,1.15304,5.724
8.06801,0.16136,1.15622,5.720
8.09101,0.16182,1.15927,5.718
8.11482,0.16230,1.16229,5.726
8.13795,0.16276,1.16527,5.730
8.16024,0.16320,1.16840,5.722
8.18276,0.16366,1.17139,5.727
8.20550,0.16411,1.17418,5.725
8.22783,0.16456,1.17712,5.721
8.24932,0.16499,1.18011,5.723
8.27126,0.16543,1.18289,5.722
8.29329,0.16587,1.18567,5.730
8.31505,0.16630,1.18852,5.726
8.33631,0.16673,1.19144,5.717
8.35859,0.16717,1.19415,5.723
8.37992,0.16760,1.19700,5.726
8.40088,0.16802,1.19988,5.726
8.42265,0.16845,1.20263,5.728
8.44398,0.16888,1.20525,5.730
8.46459,0.16929,1.20815,5.725
8.48553,0.16971,1.21097,5.714
8.50724,0.17014,1.21360,5.721
8.52830,0.17057,1.21631,5.727
8.54902,0.17098,1.21906,5.719
8.57046,0.17141,1.22173,5.725
8.59138,0.17183,1.22441,5.734
8.61211,0.17224,1.22719,5.730
8.63302,0.17266,1.22985,5.719
8.65411,0.17308,1.23249,5.725
8.67447,0.17349,1.23530,5.725
8.69544,0.17391,1.23803,5.726
8.71632,0.17433,1.24070,5.730
8.73752,0.17475,1.24349,5.729
8.75869,0.17517,1.24625,5.729
8.77985,0.17560,1.24886,5.731
8.80055,0.17601,1.25166,5.723
8.82133,0.17643,1.25433,5.722
8.84283,0.17686,1.25701,5.733
8.86364,0.17727,1.25983,5.723
8.88530,0.17771,1.26251,5.732
8.90625,0.17812,1.26524,5.727
8.92744,0.17855,1.26800,5.725
8.94894,0.17898,1.27068,5.730
8.96990,0.17940,1.27353,5.738
8.99119,0.17982,1.27637,5.730
9.01267,0.18025,1.27908,5.736
9.03382,0.18068,1.28192,5.722
9.05565,0.18111,1.28465,5.732
9.07739,0.18155,1.28746,5.730
9.09935,0.18199,1.29037,5.720
9.12126,0.18243,1.29318,5.733
9.14316,0.18286,1.29607,5.742
9.16529,0.18331,1.29899,5.728
9.18736,0.18375,1.30179,5.734
9.20953,0.18419,1.30461,5.748
9.23133,0.18463,1.30756,5.727
9.25403,0.18508,1.31038,5.738
9.27643,0.18553,1.31328,5.742
9.29883,0.18598,1.31632,5.732
9.32169,0.18643,1.31914,5.744
9.34449,0.18689,1.32208,5.738
9.36783,0.18736,1.32513,5.734
9.39119,0.18782,1.32809,5.745
9.41453,0.18829,1.33108,5.745
9.43729,0.18875,1.33424,5.735
9.46104,0.18922,1.33725,5.730
9.48442,0.18969,1.34030,5.746
9.50778,0.19016,1.34347,5.739
9.53184,0.19064,1.34655,5.746
9.55544,0.19111,1.34965,5.745
9.57965,0.19159,1.35287,5.733
9.60419,0.19208,1.35602,5.739
9.62886,0.19258,1.35918,5.740
9.65309,0.19306,1.36253,5.742
9.67828,0.19357,1.36576,5.743
9.70301,0.19406,1.36896,5.747
9.72763,0.19455,1.37231,5.733
9.75268,0.19505,1.37563,5.745
9.77824,0.19556,1.37894,5.739
9.80331,0.19607,1.38238,5.743
9.82912,0.19658,1.38567,5.747
9.85526,0.19711,1.38908,5.746
9.88099,0.19762,1.39259,5.737
9.90771,0.19815,1.39606,5.742
9.93437,0.19869,1.39961,5.746
9.96046,0.19921,1.40319,5.744
9.98797,0.19976,1.40675,5.749
10.01469,0.20029,1.41033,5.742
10.04162,0.20083,1.41407,5.746
10.06994,0.20140,1.41765,5.743
10.09840,0.20197,1.42135,5.746
10.12633,0.20253,1.42515,5.747
10.15534,0.20311,1.42886,5.755
10.18392,0.20368,1.43267,5.748
10.21309,0.20426,1.43650,5.742
10.24278,0.20486,1.44040,5.758
10.27189,0.20544,1.44438,5.750
10.30181,0.20604,1.44840,5.739
10.33224,0.20664,1.45232,5.753
10.36268,0.20725,1.45639,5.746
10.39333,0.20787,1.46042,5.742
10.42431,0.20849,1.46447,5.750
10.45504,0.20910,1.46858,5.745
10.48646,0.20973,1.47262,5.748
10.51761,0.21035,1.47677,5.750
10.54866,0.21097,1.48097,5.743
10.58020,0.21160,1.48494,5.747
10.61171,0.21223,1.48912,5.742
10.64314,0.21286,1.49338,5.740
10.67542,0.21351,1.49754,5.746
10.70693,0.21414,1.50182,5.747
10.73899,0.21478,1.50612,5.737
10.77118,0.21542,1.51026,5.745
10.80247,0.21605,1.51454,5.739
10.83469,0.21669,1.51883,5.744
10.86663,0.21733,1.52300,5.755
10.89862,0.21797,1.52732,5.746
10.93067,0.21861,1.53159,5.742
10.96325,0.21926,1.53574,5.747
10.99520,0.21990,1.54010,5.735
11.02759,0.22055,1.54431,5.746
11.05927,0.22119,1.54860,5.749
11.09156,0.22183,1.55288,5.746
11.12375,0.22248,1.55720,5.730
11.15649,0.22313,1.56145,5.745
11.18871,0.22377,1.56585,5.745
11.22090,0.22442,1.57017,5.736
11.25310,0.22506,1.57440,5.750
11.28526,0.22571,1.57873,5.742
11.31692,0.22634,1.58307,5.736
11.34963,0.22699,1.58731,5.746
11.38149,0.22763,1.59167,5.741
11.41335,0.22827,1.59602,5.733
11.44608,0.22892,1.60035,5.744
11.47829,0.22957,1.60480,5.739
11.51014,0.23020,1.60907,5.738
11.54254,0.23085,1.61334,5.742
11.57396,0.23148,1.61776,5.726
11.60643,0.23213,1.62211,5.746
11.63799,0.23276,1.62639,5.726
11.67022,0.23340,1.63080,5.734
11.70269,0.23405,1.63513,5.746
11.73449,0.23469,1.63953,5.739
11.76644,0.23533,1.64390,5.737
11.79843,0.23597,1.64826,5.727
11.82977,0.23660,1.65255,5.730
11.86159,0.23723,1.65688,5.738
11.89262,0.23785,1.66119,5.730
11.92415,0.23848,1.66539,5.726
11.95552,0.23911,1.66970,5.726
11.98693,0.23974,1.67405,5.731
12.01811,0.24036,1.67831,5.730
12.04922,0.24098,1.68258,5.729
12.07968,0.24159,1.68688,5.725
12.11089,0.24222,1.69110,5.731
12.14135,0.24283,1.69535,5.729
12.17191,0.24344,1.69964,5.716
12.20272,0.24405,1.70389,5.724
12.23292,0.24466,1.70815,5.732
12.26313,0.24526,1.71239,5.722
12.29327,0.24587,1.71662,5.723
12.32348,0.24647,1.72084,5.725
12.35284,0.24706,1.72495,5.720
12.38263,0.24765,1.72905,5.730
12.41188,0.24824,1.73325,5.723
12.44109,0.24882,1.73732,5.715
12.47060,0.24941,1.74138,5.726
12.49950,0.24999,1.74561,5.718
12.52812,0.25056,1.74977,5.715
12.55676,0.25114,1.75384,5.719
12.58512,0.25170,1.75792,5.717
12.61276,0.25226,1.76200,5.713
12.64107,0.25282,1.76600,5.708
12.66893,0.25338,1.77007,5.717
12.69623,0.25392,1.77404,5.709
12.72360,0.25447,1.77797,5.707
12.75092,0.25502,1.78196,5.707
12.77729,0.25555,1.78594,5.698
12.80387,0.25608,1.78982,5.706
12.82985,0.25660,1.79362,5.702
12.85483,0.25710,1.79738,5.692
12.88065,0.25761,1.80110,5.704
12.90513,0.25810,1.80483,5.696
12.92974,0.25859,1.80857,5.695
12.95468,0.25909,1.81216,5.693
12.97889,0.25958,1.81581,5.682
13.00318,0.26006,1.81942,5.690
13.02726,0.26055,1.82293,5.692
13.05057,0.26101,1.82647,5.687
13.07446,0.26149,1.82994,5.694
13.09730,0.26195,1.83341,5.694
13.11954,0.26239,1.83686,5.675
13.14240,0.26285,1.84024,5.684
13.16512,0.26330,1.84375,5.677
13.18721,0.26374,1.84713,5.679
13.20968,0.26419,1.85043,5.675
13.23122,0.26462,1.85381,5.674
13.25377,0.26508,1.85708,5.673
13.27569,0.26551,1.86041,5.675
13.29722,0.26594,1.86367,5.665
13.31858,0.26637,1.86685,5.667
13.34001,0.26680,1.87008,5.663
13.36130,0.26723,1.87333,5.656
13.38218,0.26764,1.87653,5.670
13.40291,0.26806,1.87965,5.664
13.42361,0.26847,1.88275,5.662
13.44447,0.26889,1.88584,5.664
13.46485,0.26930,1.88896,5.660
13.48534,0.26971,1.89201,5.651
13.50610,0.27012,1.89500,5.664
13.52626,0.27053,1.89817,5.660
13.54652,0.27093,1.90123,5.661
13.56665,0.27133,1.90422,5.655
13.58699,0.27174,1.90732,5.659
13.60792,0.27216,1.91036,5.663
13.62786,0.27256,1.91335,5.658
13.64757,0.27295,1.91636,5.645
13.66811,0.27336,1.91948,5.653
13.68849,0.27377,1.92255,5.644
13.70831,0.27417,1.92562,5.656
13.72893,0.27458,1.92867,5.650
13.74920,0.27498,1.93174,5.638
13.77005,0.27540,1.93480,5.645
13.79019,0.27580,1.93789,5.649
13.81054,0.27621,1.94099,5.639
13.83098,0.27662,1.94402,5.643
13.85138,0.27703,1.94716,5.647
13.87205,0.27744,1.95030,5.642
13.89279,0.27786,1.95338,5.645
13.91373,0.27827,1.95650,5.656
13.93422,0.27868,1.95967,5.638
13.95506,0.27910,1.96273,5.639
13.97633,0.27953,1.96595,5.644
13.99755,0.27995,1.96904,5.636
14.01914,0.28038,1.97221,5.634
14.04029,0.28081,1.97541,5.639
14.06192,0.28124,1.97862,5.633
14.08355,0.28167,1.98182,5.633
14.10484,0.28210,1.98496,5.634
14.12676,0.28254,1.98820,5.634
14.14813,0.28296,1.99151,5.614
14.17022,0.28340,1.99459,5.626
14.19290,0.28386,1.99777,5.633
14.21472,0.28429,2.00102,5.612
14.23721,0.28474,2.00427,5.632
14.25992,0.28520,2.00747,5.627
14.28253,0.28565,2.01079,5.619
14.30556,0.28611,2.01393,5.623
14.32842,0.28657,2.01715,5.620
14.35140,0.28703,2.02035,5.613
14.37431,0.28749,2.02359,5.616
14.39760,0.28795,2.02695,5.617
14.42079,0.28842,2.03025,5.610
14.44467,0.28889,2.03354,5.620
14.46850,0.28937,2.03698,5.603
14.49229,0.28985,2.04038,5.614
14.51663,0.29033,2.04364,5.602
14.54140,0.29083,2.04697,5.604
14.56633,0.29133,2.05026,5.607
14.59143,0.29183,2.05364,5.597
14.61646,0.29233,2.05708,5.601
14.64208,0.29284,2.06046,5.598
14.66753,0.29335,2.06389,5.581
14.69291,0.29386,2.06736,5.585
14.71921,0.29438,2.07085,5.587
14.74540,0.29491,2.07431,5.583
14.77201,0.29544,2.07779,5.589
14.79930,0.29599,2.08126,5.575
14.82610,0.29652,2.08461,5.586
14.85333,0.29707,2.08804,5.569
14.88002,0.29760,2.09138,5.566
14.90777,0.29816,2.09469,5.574
14.93526,0.29871,2.09797,5.561
14.96324,0.29926,2.10132,5.561
14.99152,0.29983,2.10453,5.560
15.00229,0.30040,2.10780,5.549
15.00537,0.30097,2.11088,5.560
15.00844,0.30155,2.11395,5.546
15.01137,0.30215,2.11688,5.541
15.01417,0.30273,2.11968,5.536
15.01699,0.30333,2.12250,5.529
15.01974,0.30392,2.12525,5.524
15.02241,0.30453,2.12792,5.529
15.02508,0.30513,2.13059,5.523
15.02750,0.30575,2.13301,5.512
15.02986,0.30637,2.13537,5.515
15.03228,0.30699,2.13779,5.500
15.03458,0.30760,2.14009,5.489
15.03677,0.30824,2.14228,5.499
15.03889,0.30887,2.14440,5.470
15.04089,0.30950,2.14640,5.470
15.04293,0.31014,2.14844,5.475
15.04489,0.31078,2.15040,5.458
15.04678,0.31142,2.15229,5.445
15.04851,0.31208,2.15402,5.454
15.05020,0.31274,2.15571,5.443
15.05186,0.31339,2.15737,5.430
15.05333,0.31404,2.15884,5.425
15.05482,0.31469,2.16033,5.409
15.05616,0.31535,2.16167,5.391
15.05742,0.31600,2.16293,5.384
15.05868,0.31666,2.16419,5.385
15.05976,0.31732,2.16527,5.372
15.06084,0.31798,2.16635,5.355
15.06186,0.31864,2.16737,5.351
15.06272,0.31931,2.16823,5.348
15.06355,0.31995,2.16906,5.322
15.06432,0.32061,2.16983,5.320