File: fss/fss_045_1.txt
""
"Test Method","Tensile_R_yu.msm"
"Sample I. D.","10-1-304TD1 Hyunjin.mss"
"Specimen Number","9"

"Extension (mm)","Extensometer_A (mm/mm)","Extensometer_T (mm)","Load (kN)"

-0.00001,0.00000,0.00003,-0.005
-0.00008,0.00000,-0.00001,0.001
-0.00008,0.00000,0.00003,0.003
0.00006,0.00000,0.00002,0.001
0.00002,0.00000,0.00006,0.018
0.00047,0.00001,0.00013,0.045
0.00081,0.00002,0.00016,0.079
0.00130,0.00003,0.00021,0.121
0.00182,0.00004,0.00032,0.170
0.00241,0.00005,0.00033,0.227
0.00345,0.00007,0.00045,0.297
0.00479,0.00010,0.00057,0.395
0.00659,0.00013,0.00071,0.526
0.00901,0.00018,0.00090,0.678
0.01156,0.00023,0.00108,0.843
0.01439,0.00029,0.00129,1.028
0.01810,0.00036,0.00151,1.231
0.02213,0.00044,0.00182,1.472
0.02678,0.00054,0.00208,1.734
0.03210,0.00064,0.00237,2.004
0.03773,0.00075,0.00274,2.303
0.04401,0.00088,0.00316,2.596
0.05093,0.00102,0.00366,2.880
0.05961,0.00119,0.00423,3.160
0.07009,0.00140,0.00504,3.370
0.08142,0.00163,0.00605,3.514
0.09504,0.00190,0.00734,3.624
0.11046,0.00221,0.00890,3.679
0.12738,0.00255,0.01068,3.718
0.14614,0.00292,0.01256,3.747
0.16608,0.00332,0.01460,3.766
0.18666,0.00373,0.01674,3.775
0.20863,0.00417,0.01898,3.799
0.23182,0.00464,0.02135,3.828
0.25539,0.00511,0.02363,3.851
0.27925,0.00559,0.02599,3.872
0.30432,0.00609,0.02841,3.886
0.32981,0.00660,0.03083,3.903
0.35570,0.00711,0.03328,3.922
0.38158,0.00763,0.03583,3.949
0.40870,0.00817,0.03835,3.972
0.43596,0.00872,0.04096,3.993
0.46349,0.00927,0.04359,4.018
0.49158,0.00983,0.04627,4.049
0.52011,0.01040,0.04899,4.063
0.54881,0.01098,0.05170,4.092
0.57810,0.01156,0.05445,4.112
0.60763,0.01215,0.05722,4.124
0.63731,0.01275,0.06002,4.154
0.66758,0.01335,0.06288,4.182
0.69840,0.01397,0.06571,4.215
0.72837,0.01457,0.06866,4.235
0.75962,0.01519,0.07160,4.256
0.79165,0.01583,0.07459,4.284
0.82387,0.01648,0.07761,4.307
0.85718,0.01714,0.08070,4.332
0.89021,0.01780,0.08384,4.355
0.92377,0.01848,0.08699,4.384
0.95731,0.01915,0.09016,4.413
0.99073,0.01981,0.09336,4.444
1.02478,0.02050,0.09658,4.458
1.05881,0.02118,0.09985,4.479
1.09344,0.02187,0.10304,4.496
1.12770,0.02255,0.10628,4.525
1.16185,0.02324,0.10948,4.553
1.19651,0.02393,0.11267,4.574
1.23081,0.02462,0.11583,4.600
1.26587,0.02532,0.11904,4.623
1.30073,0.02601,0.12237,4.637
1.33597,0.02672,0.12565,4.664
1.37204,0.02744,0.12894,4.688
1.40808,0.02816,0.13223,4.711
1.44419,0.02888,0.13553,4.732
1.48032,0.02961,0.13883,4.756
1.51696,0.03034,0.14222,4.774
1.55360,0.03107,0.14562,4.792
1.59034,0.03181,0.14901,4.815
1.62756,0.03255,0.15243,4.838
1.66473,0.03329,0.15584,4.860
1.70173,0.03403,0.15932,4.883
1.73857,0.03477,0.16275,4.897
1.77583,0.03552,0.16622,4.916
1.81311,0.03626,0.16971,4.937
1.85032,0.03701,0.17309,4.947
1.88791,0.03776,0.17653,4.964
1.92523,0.03850,0.17989,4.988
1.96258,0.03925,0.18332,5.017
1.99986,0.04000,0.18669,5.028
2.03768,0.04075,0.19008,5.039
2.07480,0.04150,0.19354,5.061
2.11236,0.04225,0.19697,5.068
2.15018,0.04300,0.20039,5.097
2.18760,0.04375,0.20379,5.104
2.22515,0.04450,0.20719,5.121
2.26204,0.04524,0.21061,5.146
2.29952,0.04599,0.21405,5.157
2.33704,0.04674,0.21748,5.175
2.37471,0.04749,0.22092,5.183
2.41241,0.04825,0.22431,5.199
2.44973,0.04899,0.22773,5.220
2.48712,0.04974,0.23111,5.229
2.52436,0.05049,0.23449,5.250
2.56187,0.05124,0.23788,5.261
2.59909,0.05198,0.24117,5.277
2.63670,0.05273,0.24453,5.285
2.67458,0.05349,0.24785,5.295
2.71185,0.05424,0.25122,5.310
2.74910,0.05498,0.25451,5.329
2.78575,0.05572,0.25789,5.334
2.82294,0.05646,0.26132,5.351
2.85986,0.05720,0.26465,5.365
2.89699,0.05794,0.26798,5.366
2.93453,0.05869,0.27128,5.382
2.97164,0.05943,0.27459,5.392
3.00843,0.06017,0.27790,5.403
3.04521,0.06090,0.28117,5.424
3.08239,0.06165,0.28445,5.432
3.11900,0.06238,0.28771,5.446
3.15640,0.06313,0.29098,5.449
3.19356,0.06387,0.29419,5.462
3.23047,0.06461,0.29751,5.465
3.26728,0.06535,0.30081,5.486
3.30371,0.06607,0.30405,5.496
3.34037,0.06681,0.30728,5.511
3.37711,0.06754,0.31048,5.521
3.41415,0.06828,0.31368,5.521
3.45127,0.06903,0.31689,5.535
3.48768,0.06975,0.32013,5.539
3.52411,0.07048,0.32335,5.557
3.56029,0.07121,0.32652,5.554
3.59662,0.07193,0.32967,5.573
3.63307,0.07266,0.33282,5.581
3.66941,0.07339,0.33596,5.582
3.70620,0.07412,0.33914,5.597
3.74273,0.07485,0.34224,5.603
3.77905,0.07558,0.34536,5.608
3.81428,0.07629,0.34843,5.614
3.85019,0.07700,0.35153,5.624
3.88598,0.07772,0.35459,5.640
3.92195,0.07844,0.35764,5.640
3.95803,0.07916,0.36068,5.642
3.99373,0.07987,0.36377,5.644
4.02896,0.08058,0.36681,5.648
4.06449,0.08129,0.36986,5.664
4.09942,0.08199,0.37294,5.676
4.13416,0.08268,0.37596,5.671
4.16928,0.08339,0.37895,5.679
4.20459,0.08409,0.38188,5.682
4.23978,0.08480,0.38483,5.688
4.27411,0.08548,0.38782,5.691
4.30883,0.08618,0.39078,5.698
4.34276,0.08686,0.39368,5.705
4.37685,0.08754,0.39653,5.716
4.41058,0.08821,0.39943,5.720
4.44440,0.08889,0.40216,5.723
4.47824,0.08956,0.40504,5.721
4.51194,0.09024,0.40785,5.724
4.54491,0.09090,0.41067,5.737
4.57799,0.09156,0.41344,5.744
4.60993,0.09220,0.41615,5.752
4.64216,0.09284,0.41884,5.752
4.67398,0.09348,0.42155,5.757
4.70596,0.09412,0.42415,5.752
4.73749,0.09475,0.42680,5.760
4.76895,0.09538,0.42944,5.771
4.80006,0.09600,0.43200,5.774
4.83062,0.09661,0.43462,5.776
4.86073,0.09721,0.43711,5.777
4.89049,0.09781,0.43960,5.779
4.92060,0.09841,0.44212,5.776
4.95053,0.09901,0.44455,5.784
4.98020,0.09960,0.44691,5.785
5.00902,0.10018,0.44934,5.792
5.03807,0.10076,0.45164,5.802
5.06684,0.10134,0.45400,5.803
5.09516,0.10190,0.45628,5.794
5.12281,0.10246,0.45855,5.806
5.15086,0.10302,0.46080,5.801
5.17838,0.10357,0.46307,5.812
5.20618,0.10412,0.46533,5.818
5.23352,0.10467,0.46749,5.819
5.26064,0.10521,0.46976,5.817
5.28756,0.10575,0.47193,5.824
5.31394,0.10628,0.47408,5.822
5.34018,0.10680,0.47615,5.824
5.36584,0.10732,0.47833,5.828
5.39195,0.10784,0.48041,5.834
5.41786,0.10836,0.48250,5.838
5.44314,0.10886,0.48453,5.830
5.46854,0.10937,0.48659,5.828
5.49407,0.10988,0.48862,5.832
5.51891,0.11038,0.49068,5.838
5.54350,0.11087,0.49262,5.836
5.56770,0.11135,0.49459,5.841
5.59197,0.11184,0.49650,5.845
5.61565,0.11231,0.49842,5.839
5.63902,0.11278,0.50031,5.841
5.66249,0.11325,0.50218,5.844
5.68570,0.11371,0.50408,5.847
5.70861,0.11417,0.50597,5.854
5.73157,0.11463,0.50780,5.852
5.75429,0.11509,0.50959,5.855
5.77704,0.11554,0.51136,5.856
5.79943,0.11599,0.51316,5.852
5.82150,0.11643,0.51491,5.859
5.84362,0.11687,0.51669,5.853
5.86524,0.11730,0.51841,5.867
5.88630,0.11773,0.52013,5.865
5.90783,0.11816,0.52192,5.870
5.92948,0.11859,0.52360,5.865
5.95050,0.11901,0.52527,5.860
5.97148,0.11943,0.52696,5.860
5.99234,0.11985,0.52863,5.867
6.01338,0.12027,0.53029,5.876
6.03436,0.12069,0.53198,5.867
6.05477,0.12110,0.53349,5.866
6.07534,0.12151,0.53515,5.867
6.09598,0.12192,0.53683,5.867
6.11647,0.12233,0.53849,5.872
6.13687,0.12274,0.54014,5.876
6.15701,0.12314,0.54182,5.878
6.17764,0.12355,0.54341,5.877
6.19826,0.12397,0.54508,5.879
6.21821,0.12436,0.54663,5.880
6.23858,0.12477,0.54829,5.883
6.25864,0.12517,0.54996,5.881
6.27916,0.12558,0.55155,5.890
6.29940,0.12599,0.55313,5.892
6.31964,0.12639,0.55479,5.883
6.33939,0.12679,0.55631,5.883
6.35939,0.12719,0.55791,5.885
6.37946,0.12759,0.55947,5.895
6.39906,0.12798,0.56103,5.883
6.41858,0.12837,0.56266,5.889
6.43876,0.12878,0.56422,5.887
6.45904,0.12918,0.56584,5.887
6.47869,0.12957,0.56739,5.892
6.49880,0.12998,0.56897,5.889
6.51908,0.13038,0.57061,5.898
6.53911,0.13078,0.57219,5.895
6.55924,0.13118,0.57373,5.888
6.57917,0.13158,0.57530,5.886
6.59885,0.13198,0.57686,5.896
6.61897,0.13238,0.57845,5.900
6.63896,0.13278,0.57999,5.906
6.65886,0.13318,0.58156,5.898
6.67914,0.13358,0.58310,5.895
6.69928,0.13399,0.58463,5.896
6.71962,0.13439,0.58627,5.904
6.73920,0.13478,0.58781,5.902
6.75975,0.13519,0.58940,5.910
6.78020,0.13560,0.59097,5.910
6.80076,0.13602,0.59253,5.907
6.82138,0.13643,0.59411,5.904
6.84168,0.13683,0.59563,5.906
6.86196,0.13724,0.59721,5.912
6.88237,0.13765,0.59880,5.910
6.90319,0.13806,0.60044,5.902
6.92322,0.13846,0.60204,5.909
6.94407,0.13888,0.60367,5.909
6.96488,0.13930,0.60531,5.908
6.98555,0.13971,0.60707,5.913
7.00645,0.14013,0.60869,5.922
7.02770,0.14055,0.61033,5.915
7.04906,0.14098,0.61195,5.919
7.06999,0.14140,0.61360,5.910
7.09134,0.14183,0.61526,5.921
7.11235,0.14225,0.61693,5.918
7.13356,0.14267,0.61857,5.928
7.15485,0.14310,0.62019,5.926
7.17590,0.14352,0.62186,5.926
7.19755,0.14395,0.62352,5.923
7.21918,0.14438,0.62519,5.916
7.24066,0.14481,0.62689,5.924
7.26205,0.14524,0.62862,5.939
7.28414,0.14568,0.63027,5.939
7.30626,0.14613,0.63198,5.930
7.32820,0.14656,0.63364,5.929
7.35033,0.14701,0.63540,5.933
7.37249,0.14745,0.63708,5.935
7.39503,0.14790,0.63881,5.931
7.41726,0.14835,0.64047,5.944
7.43913,0.14878,0.64225,5.928
7.46194,0.14924,0.64394,5.934
7.48466,0.14969,0.64567,5.932
7.50706,0.15014,0.64743,5.939
7.53019,0.15060,0.64913,5.935
7.55292,0.15106,0.65085,5.944
7.57633,0.15153,0.65264,5.943
7.59952,0.15199,0.65437,5.935
7.62280,0.15246,0.65617,5.931
7.64605,0.15292,0.65794,5.935
7.66963,0.15339,0.65975,5.938
7.69297,0.15386,0.66151,5.946
7.71661,0.15433,0.66335,5.938
7.74083,0.15482,0.66513,5.941
7.76457,0.15529,0.66698,5.942
7.78923,0.15578,0.66882,5.939
7.81343,0.15627,0.67067,5.943
7.83803,0.15676,0.67254,5.948
7.86269,0.15725,0.67446,5.945
7.88704,0.15774,0.67640,5.951
7.91183,0.15824,0.67821,5.949
7.93688,0.15874,0.68014,5.941
7.96117,0.15922,0.68200,5.951
7.98623,0.15972,0.68391,5.942
8.01135,0.16023,0.68576,5.952
8.03646,0.16073,0.68770,5.945
8.06251,0.16125,0.68968,5.953
8.08838,0.16177,0.69161,5.956
8.11444,0.16229,0.69359,5.960
8.14057,0.16281,0.69560,5.951
8.16658,0.16333,0.69761,5.951
8.19295,0.16386,0.69956,5.946
8.21908,0.16438,0.70163,5.951
8.24543,0.16491,0.70369,5.952
8.27234,0.16545,0.70566,5.957
8.29862,0.16597,0.70768,5.955
8.32557,0.16651,0.70972,5.962
8.35274,0.16705,0.71171,5.958
8.37982,0.16760,0.71380,5.950
8.40695,0.16814,0.71580,5.954
8.43448,0.16869,0.71792,5.957
8.46207,0.16924,0.72003,5.957
8.48932,0.16979,0.72214,5.966
8.51750,0.17035,0.72426,5.966
8.54539,0.17091,0.72638,5.955
8.57347,0.17147,0.72854,5.956
8.60270,0.17205,0.73070,5.952
8.63132,0.17263,0.73290,5.960
8.66017,0.17320,0.73507,5.966
8.68892,0.17378,0.73719,5.965
8.71826,0.17437,0.73937,5.961
8.74700,0.17494,0.74156,5.961
8.77638,0.17553,0.74372,5.961
8.80530,0.17611,0.74593,5.955
8.83469,0.17669,0.74813,5.967
8.86433,0.17729,0.75032,5.962
8.89372,0.17787,0.75252,5.964
8.92325,0.17847,0.75470,5.961
8.95306,0.17906,0.75691,5.963
8.98299,0.17966,0.75916,5.964
9.01228,0.18025,0.76141,5.965
9.04220,0.18084,0.76363,5.960
9.07170,0.18143,0.76588,5.960
9.10196,0.18204,0.76817,5.963
9.13216,0.18264,0.77040,5.971
9.16237,0.18325,0.77270,5.965
9.19257,0.18385,0.77498,5.968
9.22269,0.18445,0.77727,5.967
9.25292,0.18506,0.77958,5.959
9.28287,0.18566,0.78188,5.959
9.31343,0.18627,0.78425,5.970
9.34383,0.18688,0.78652,5.968
9.37437,0.18749,0.78880,5.971
9.40519,0.18810,0.79109,5.970
9.43613,0.18872,0.79338,5.963
9.46643,0.18933,0.79574,5.958
9.49718,0.18994,0.79800,5.959
9.52744,0.19055,0.80033,5.963
9.55825,0.19117,0.80267,5.962
9.58896,0.19178,0.80499,5.965
9.61970,0.19239,0.80736,5.962
9.65136,0.19303,0.80967,5.957
9.68244,0.19365,0.81199,5.958
9.71337,0.19427,0.81430,5.959
9.74456,0.19489,0.81669,5.963
9.77544,0.19551,0.81909,5.964
9.80665,0.19613,0.82144,5.962
9.83775,0.19676,0.82375,5.960
9.86902,0.19738,0.82610,5.949
9.90035,0.19801,0.82846,5.958
9.93181,0.19864,0.83085,5.953
9.96306,0.19926,0.83320,5.961
9.99436,0.19989,0.83563,5.965
10.02535,0.20051,0.83799,5.962
10.05678,0.20114,0.84037,5.955
10.08848,0.20177,0.84271,5.953
10.11971,0.20239,0.84511,5.952
10.15133,0.20303,0.84757,5.960
10.18309,0.20366,0.84999,5.953
10.21500,0.20430,0.85232,5.968
10.24633,0.20493,0.85472,5.956
10.27814,0.20556,0.85710,5.963
10.30953,0.20619,0.85949,5.953
10.34123,0.20682,0.86188,5.944
10.37281,0.20746,0.86431,5.954
10.40416,0.20808,0.86665,5.952
10.43614,0.20872,0.86907,5.950
10.46761,0.20935,0.87146,5.947
10.49920,0.20998,0.87391,5.952
10.53094,0.21062,0.87624,5.950
10.56199,0.21124,0.87867,5.943
10.59346,0.21187,0.88099,5.937
10.62476,0.21250,0.88339,5.955
10.65636,0.21313,0.88574,5.951
10.68798,0.21376,0.88810,5.954
10.71987,0.21440,0.89043,5.952
10.75106,0.21502,0.89288,5.944
10.78297,0.21566,0.89526,5.939
10.81411,0.21628,0.89777,5.948
10.84577,0.21692,0.90021,5.936
10.87691,0.21754,0.90262,5.938
10.90853,0.21817,0.90510,5.946
10.94027,0.21881,0.90757,5.944
10.97176,0.21944,0.90999,5.942
11.00279,0.22006,0.91243,5.942
11.03415,0.22068,0.91487,5.933
11.06473,0.22129,0.91725,5.934
11.09602,0.22192,0.91969,5.936
11.12653,0.22253,0.92217,5.935
11.15756,0.22315,0.92448,5.934
11.18814,0.22376,0.92690,5.938
11.21901,0.22438,0.92932,5.931
11.24983,0.22500,0.93164,5.932
11.28044,0.22561,0.93403,5.931
11.31111,0.22622,0.93633,5.927
11.34161,0.22683,0.93877,5.929
11.37203,0.22744,0.94116,5.931
11.40223,0.22804,0.94352,5.930
11.43243,0.22865,0.94592,5.934
11.46286,0.22926,0.94831,5.928
11.49324,0.22986,0.95070,5.932
11.52336,0.23047,0.95301,5.924
11.55343,0.23107,0.95538,5.927
11.58312,0.23166,0.95781,5.921
11.61290,0.23226,0.96018,5.924
11.64294,0.23286,0.96260,5.923
11.67264,0.23345,0.96500,5.922
11.70226,0.23405,0.96733,5.920
11.73204,0.23464,0.96972,5.921
11.76152,0.23523,0.97203,5.912
11.79040,0.23581,0.97443,5.911
11.81974,0.23639,0.97676,5.909
11.84800,0.23696,0.97917,5.916
11.87682,0.23754,0.98151,5.914
11.90513,0.23810,0.98382,5.914
11.93368,0.23867,0.98612,5.918
11.96157,0.23923,0.98842,5.909
11.99015,0.23980,0.99068,5.912
12.01830,0.24037,0.99297,5.916
12.04594,0.24092,0.99525,5.903
12.07362,0.24147,0.99746,5.897
12.10080,0.24202,0.99976,5.899
12.12773,0.24255,1.00197,5.907
12.15477,0.24310,1.00418,5.893
12.18175,0.24363,1.00648,5.897
12.20857,0.24417,1.00868,5.907
12.23528,0.24471,1.01089,5.894
12.26126,0.24523,1.01308,5.897
12.28707,0.24574,1.01520,5.893
12.31261,0.24625,1.01737,5.882
12.33814,0.24676,1.01952,5.886
12.36356,0.24727,1.02167,5.880
12.38841,0.24777,1.02382,5.901
12.41392,0.24828,1.02589,5.887
12.43881,0.24878,1.02804,5.891
12.46404,0.24928,1.03013,5.886
12.48913,0.24978,1.03226,5.881
12.51419,0.25028,1.03435,5.885
12.53945,0.25079,1.03643,5.884
12.56418,0.25128,1.03856,5.889
12.58892,0.25178,1.04069,5.882
12.61353,0.25227,1.04284,5.882
12.63720,0.25274,1.04490,5.876
12.66126,0.25323,1.04698,5.883
12.68468,0.25369,1.04911,5.879
12.70867,0.25417,1.05124,5.882
12.73209,0.25464,1.05328,5.881
12.75574,0.25511,1.05525,5.871
12.77963,0.25559,1.05729,5.866
12.80290,0.25606,1.05939,5.865
12.82617,0.25652,1.06143,5.868
12.84966,0.25699,1.06351,5.874
12.87310,0.25746,1.06556,5.866
12.89610,0.25792,1.06759,5.876
12.91965,0.25839,1.06965,5.869
12.94252,0.25885,1.07165,5.862
12.96595,0.25932,1.07366,5.866
12.98941,0.25979,1.07584,5.863
13.01331,0.26027,1.07798,5.856
13.03644,0.26073,1.08005,5.857
13.05972,0.26119,1.08226,5.857
13.08265,0.26165,1.08438,5.863
13.10577,0.26212,1.08650,5.854
13.12936,0.26259,1.08869,5.858
13.15180,0.26304,1.09075,5.849
13.17496,0.26350,1.09287,5.857
13.19807,0.26396,1.09502,5.848
13.22095,0.26442,1.09715,5.860
13.24371,0.26487,1.09925,5.849
13.26659,0.26533,1.10141,5.859
13.28903,0.26578,1.10353,5.853
13.31182,0.26624,1.10553,5.850
13.33462,0.26669,1.10757,5.849
13.35713,0.26714,1.10966,5.841
13.37970,0.26759,1.11173,5.837
13.40188,0.26804,1.11392,5.847
13.42443,0.26849,1.11608,5.839
13.44668,0.26893,1.11808,5.850
13.46960,0.26939,1.12015,5.845
13.49191,0.26984,1.12225,5.844
13.51447,0.27029,1.12440,5.835
13.53750,0.27075,1.12647,5.833
13.56017,0.27120,1.12862,5.840
13.58272,0.27165,1.13079,5.832
13.60488,0.27210,1.13292,5.834
13.62799,0.27256,1.13508,5.837
13.65055,0.27301,1.13727,5.835
13.67276,0.27346,1.13941,5.829
13.69526,0.27391,1.14159,5.833
13.71803,0.27436,1.14372,5.832
13.74026,0.27481,1.14591,5.822
13.76312,0.27526,1.14810,5.821
13.78616,0.27572,1.15039,5.828
13.80868,0.27617,1.15273,5.818
13.83134,0.27663,1.15504,5.827
13.85382,0.27708,1.15728,5.826
13.87679,0.27754,1.15961,5.816
13.89953,0.27799,1.16195,5.808
13.92191,0.27844,1.16431,5.809
13.94480,0.27890,1.16670,5.810
13.96761,0.27935,1.16905,5.799
13.99046,0.27981,1.17138,5.808
14.01310,0.28026,1.17381,5.813
14.03609,0.28072,1.17621,5.809
14.05913,0.28118,1.17860,5.807
14.08227,0.28165,1.18092,5.798
14.10521,0.28210,1.18335,5.804
14.12797,0.28256,1.18585,5.786
14.15098,0.28302,1.18819,5.789
14.17386,0.28348,1.19069,5.795
14.19664,0.28393,1.19314,5.794
14.21978,0.28440,1.19556,5.786
14.24266,0.28485,1.19800,5.780
14.26573,0.28531,1.20055,5.772
14.28894,0.28578,1.20309,5.766
14.31214,0.28624,1.20566,5.771
14.33522,0.28670,1.20813,5.764
14.35828,0.28717,1.21059,5.766
14.38117,0.28762,1.21307,5.760
14.40458,0.28809,1.21550,5.764
14.42775,0.28855,1.21797,5.752
14.45078,0.28902,1.22039,5.739
14.47416,0.28948,1.22280,5.738
14.49763,0.28995,1.22523,5.728
14.52100,0.29042,1.22759,5.724
14.54432,0.29089,1.22985,5.720
14.56813,0.29136,1.23199,5.715
14.59193,0.29184,1.23425,5.695
14.61546,0.29231,1.23654,5.687
14.63877,0.29278,1.23896,5.687
14.66289,0.29326,1.24134,5.671
14.68679,0.29374,1.24359,5.670
14.71007,0.29420,1.24557,5.656
14.73422,0.29468,1.24762,5.647
14.75820,0.29516,1.24975,5.626
14.78249,0.29565,1.25196,5.613
14.80663,0.29613,1.25423,5.605
14.83114,0.29662,1.25651,5.594
14.85573,0.29711,1.25880,5.575
14.88006,0.29760,1.26128,5.555
14.90464,0.29809,1.26379,5.541
14.92960,0.29859,1.26642,5.521
14.95447,0.29909,1.26917,5.491
14.97937,0.29959,1.27223,5.460
15.00062,0.30010,1.27536,5.441
15.00390,0.30061,1.27864,5.412
15.00741,0.30113,1.28215,5.382
15.01139,0.30166,1.28613,5.343
15.01542,0.30218,1.29015,5.295
15.01944,0.30272,1.29418,5.254
15.02335,0.30326,1.29808,5.208
15.02795,0.30381,1.30268,5.153
15.03339,0.30436,1.30813,5.088
15.03855,0.30492,1.31329,5.013
15.04386,0.30549,1.31860,4.922