File: fss/tension_R17.txt
""
"Test Method","Tensile_R_yu.msm"
"Sample I. D.","10-1-304TD1 Hyunjin.mss"
"Specimen Number","10"

"Extension (mm)","Extensometer_A (mm/mm)","Extensometer_T (mm)","Load (kN)"

-0.00008,0.00000,-0.00005,0.000
-0.00017,0.00000,-0.00005,0.006
-0.00010,0.00000,-0.00001,0.009
0.00012,0.00000,-0.00005,0.003
-0.00001,0.00000,-0.00001,0.018
0.00021,0.00000,-0.00002,0.018
0.00013,0.00000,0.00002,0.039
0.00001,0.00000,0.00001,0.034
0.00038,0.00001,0.00004,0.044
0.00037,0.00001,0.00009,0.064
0.00055,0.00001,0.00007,0.090
0.00071,0.00001,0.00014,0.108
0.00092,0.00002,0.00017,0.125
0.00113,0.00002,0.00020,0.166
0.00118,0.00002,0.00023,0.181
0.00184,0.00004,0.00031,0.229
0.00218,0.00004,0.00034,0.264
0.00286,0.00006,0.00041,0.311
0.00334,0.00007,0.00045,0.366
0.00393,0.00008,0.00058,0.403
0.00477,0.00010,0.00066,0.476
0.00588,0.00012,0.00074,0.534
0.00714,0.00014,0.00085,0.626
0.00827,0.00017,0.00098,0.704
0.00972,0.00019,0.00109,0.796
0.01125,0.00022,0.00120,0.895
0.01304,0.00026,0.00132,0.991
0.01518,0.00030,0.00149,1.105
0.01682,0.00034,0.00161,1.212
0.01895,0.00038,0.00177,1.343
0.02123,0.00042,0.00194,1.463
0.02350,0.00047,0.00207,1.590
0.02604,0.00052,0.00224,1.735
0.02879,0.00058,0.00240,1.877
0.03179,0.00064,0.00257,2.027
0.03475,0.00070,0.00274,2.174
0.03791,0.00076,0.00297,2.335
0.04108,0.00082,0.00319,2.490
0.04495,0.00090,0.00344,2.652
0.04879,0.00098,0.00379,2.809
0.05307,0.00106,0.00408,2.953
0.05747,0.00115,0.00443,3.094
0.06203,0.00124,0.00488,3.215
0.06705,0.00134,0.00530,3.319
0.07266,0.00145,0.00578,3.412
0.07852,0.00157,0.00635,3.485
0.08508,0.00170,0.00692,3.549
0.09182,0.00184,0.00756,3.601
0.09932,0.00199,0.00824,3.648
0.10720,0.00214,0.00899,3.677
0.11581,0.00232,0.00975,3.697
0.12488,0.00250,0.01056,3.718
0.13399,0.00268,0.01140,3.733
0.14324,0.00286,0.01223,3.751
0.15327,0.00307,0.01321,3.759
0.16351,0.00327,0.01406,3.779
0.17383,0.00348,0.01502,3.779
0.18462,0.00369,0.01597,3.794
0.19553,0.00391,0.01694,3.808
0.20634,0.00413,0.01795,3.814
0.21766,0.00435,0.01897,3.829
0.22912,0.00458,0.02005,3.827
0.24091,0.00482,0.02109,3.844
0.25272,0.00505,0.02218,3.855
0.26509,0.00530,0.02337,3.866
0.27712,0.00554,0.02443,3.870
0.28952,0.00579,0.02567,3.880
0.30250,0.00605,0.02682,3.896
0.31508,0.00630,0.02802,3.899
0.32759,0.00655,0.02916,3.914
0.34044,0.00681,0.03036,3.929
0.35377,0.00708,0.03155,3.942
0.36705,0.00734,0.03274,3.958
0.38038,0.00761,0.03400,3.960
0.39367,0.00787,0.03526,3.975
0.40720,0.00814,0.03646,3.982
0.42112,0.00842,0.03770,3.995
0.43512,0.00870,0.03896,4.004
0.44945,0.00899,0.04028,4.016
0.46360,0.00927,0.04154,4.038
0.47818,0.00956,0.04288,4.041
0.49321,0.00986,0.04421,4.057
0.50775,0.01015,0.04558,4.068
0.52297,0.01046,0.04689,4.077
0.53781,0.01076,0.04828,4.093
0.55264,0.01105,0.04963,4.097
0.56775,0.01136,0.05095,4.117
0.58297,0.01166,0.05227,4.121
0.59803,0.01196,0.05362,4.142
0.61345,0.01227,0.05500,4.151
0.62908,0.01258,0.05635,4.162
0.64465,0.01289,0.05769,4.177
0.65929,0.01319,0.05912,4.181
0.67505,0.01350,0.06044,4.199
0.69123,0.01382,0.06185,4.214
0.70737,0.01415,0.06326,4.221
0.72347,0.01447,0.06466,4.238
0.73954,0.01479,0.06617,4.247
0.75617,0.01512,0.06760,4.268
0.77262,0.01545,0.06912,4.271
0.78959,0.01579,0.07056,4.292
0.80609,0.01612,0.07213,4.301
0.82288,0.01646,0.07366,4.318
0.83990,0.01680,0.07512,4.330
0.85625,0.01713,0.07666,4.332
0.87344,0.01747,0.07816,4.348
0.89028,0.01781,0.07972,4.352
0.90781,0.01816,0.08119,4.378
0.92395,0.01848,0.08272,4.385
0.94151,0.01883,0.08418,4.403
0.95838,0.01917,0.08567,4.414
0.97523,0.01950,0.08721,4.418
0.99288,0.01986,0.08865,4.441
1.01010,0.02020,0.09025,4.445
1.02740,0.02055,0.09169,4.458
1.04481,0.02090,0.09320,4.478
1.06235,0.02125,0.09475,4.494
1.08014,0.02160,0.09624,4.503
1.09743,0.02195,0.09785,4.501
1.11574,0.02231,0.09923,4.524
1.13293,0.02266,0.10098,4.539
1.15191,0.02304,0.10236,4.544
1.16863,0.02337,0.10410,4.563
1.18734,0.02375,0.10556,4.570
1.20511,0.02410,0.10715,4.587
1.22346,0.02447,0.10871,4.599
1.24194,0.02484,0.11026,4.615
1.25970,0.02519,0.11196,4.616
1.27858,0.02557,0.11338,4.634
1.29623,0.02592,0.11513,4.643
1.31528,0.02631,0.11653,4.647
1.33294,0.02666,0.11828,4.672
1.35155,0.02703,0.11980,4.664
1.36947,0.02739,0.12143,4.689
1.38770,0.02775,0.12300,4.692
1.40648,0.02813,0.12462,4.704
1.42463,0.02849,0.12629,4.719
1.44309,0.02886,0.12792,4.728
1.46136,0.02923,0.12961,4.740
1.48000,0.02960,0.13117,4.745
1.49805,0.02996,0.13281,4.771
1.51644,0.03033,0.13446,4.770
1.53513,0.03070,0.13605,4.778
1.55341,0.03107,0.13768,4.800
1.57239,0.03145,0.13924,4.807
1.59059,0.03181,0.14087,4.823
1.60908,0.03218,0.14246,4.827
1.62741,0.03255,0.14410,4.835
1.64578,0.03292,0.14568,4.845
1.66450,0.03329,0.14725,4.854
1.68284,0.03366,0.14887,4.864
1.70075,0.03401,0.15049,4.866
1.71913,0.03438,0.15210,4.886
1.73764,0.03475,0.15366,4.899
1.75592,0.03512,0.15524,4.898
1.77424,0.03548,0.15689,4.914
1.79318,0.03586,0.15850,4.923
1.81109,0.03622,0.16008,4.926
1.82985,0.03660,0.16159,4.930
1.84823,0.03696,0.16313,4.956
1.86652,0.03733,0.16473,4.955
1.88479,0.03770,0.16619,4.968
1.90311,0.03806,0.16774,4.981
1.92176,0.03844,0.16935,4.981
1.93993,0.03880,0.17089,4.996
1.95816,0.03916,0.17245,4.997
1.97672,0.03953,0.17403,5.007
1.99501,0.03990,0.17562,5.029
2.01315,0.04026,0.17718,5.030
2.03144,0.04063,0.17878,5.050
2.04999,0.04100,0.18032,5.044
2.06834,0.04137,0.18196,5.058
2.08678,0.04174,0.18348,5.062
2.10535,0.04211,0.18510,5.065
2.12353,0.04247,0.18662,5.077
2.14189,0.04284,0.18816,5.074
2.16026,0.04321,0.18976,5.097
2.17869,0.04357,0.19133,5.095
2.19723,0.04394,0.19284,5.116
2.21521,0.04430,0.19446,5.118
2.23350,0.04467,0.19598,5.119
2.25157,0.04503,0.19759,5.137
2.26954,0.04539,0.19913,5.137
2.28799,0.04576,0.20070,5.157
2.30608,0.04612,0.20220,5.142
2.32425,0.04649,0.20373,5.158
2.34272,0.04685,0.20526,5.166
2.36112,0.04722,0.20673,5.171
2.37894,0.04758,0.20830,5.190
2.39723,0.04794,0.20984,5.182
2.41547,0.04831,0.21140,5.205
2.43360,0.04867,0.21294,5.202
2.45172,0.04903,0.21449,5.202
2.46974,0.04939,0.21605,5.224
2.48789,0.04976,0.21760,5.209
2.50586,0.05012,0.21913,5.227
2.52404,0.05048,0.22065,5.235
2.54201,0.05084,0.22222,5.243
2.56008,0.05120,0.22379,5.250
2.57813,0.05156,0.22534,5.249
2.59644,0.05193,0.22686,5.266
2.61451,0.05229,0.22835,5.270
2.63244,0.05265,0.22987,5.278
2.65044,0.05301,0.23140,5.277
2.66781,0.05336,0.23295,5.288
2.68618,0.05372,0.23449,5.299
2.70410,0.05408,0.23599,5.303
2.72141,0.05443,0.23751,5.309
2.73936,0.05479,0.23902,5.310
2.75729,0.05515,0.24054,5.321
2.77493,0.05550,0.24207,5.323
2.79296,0.05586,0.24352,5.326
2.81060,0.05621,0.24500,5.340
2.82869,0.05657,0.24656,5.347
2.84648,0.05693,0.24804,5.354
2.86453,0.05729,0.24951,5.353
2.88267,0.05765,0.25104,5.361
2.90037,0.05801,0.25254,5.374
2.91814,0.05836,0.25404,5.367
2.93586,0.05872,0.25543,5.376
2.95370,0.05907,0.25693,5.384
2.97157,0.05943,0.25842,5.389
2.98882,0.05978,0.25996,5.395
3.00664,0.06013,0.26143,5.400
3.02429,0.06049,0.26293,5.404
3.04213,0.06084,0.26431,5.410
3.05951,0.06119,0.26577,5.420
3.07723,0.06154,0.26721,5.415
3.09505,0.06190,0.26863,5.430
3.11272,0.06225,0.27006,5.436
3.13011,0.06260,0.27153,5.428
3.14761,0.06295,0.27296,5.446
3.16538,0.06331,0.27446,5.441
3.18260,0.06365,0.27589,5.452
3.20026,0.06401,0.27736,5.454
3.21771,0.06435,0.27878,5.461
3.23531,0.06471,0.28018,5.466
3.25210,0.06504,0.28163,5.469
3.26959,0.06539,0.28305,5.475
3.28716,0.06574,0.28444,5.473
3.30418,0.06608,0.28590,5.485
3.32145,0.06643,0.28737,5.493
3.33904,0.06678,0.28880,5.491
3.35632,0.06713,0.29025,5.505
3.37364,0.06747,0.29160,5.502
3.39076,0.06782,0.29302,5.510
3.40797,0.06816,0.29445,5.509
3.42524,0.06850,0.29585,5.518
3.44201,0.06884,0.29734,5.531
3.45925,0.06918,0.29870,5.521
3.47651,0.06953,0.30011,5.539
3.49366,0.06987,0.30149,5.534
3.51026,0.07021,0.30290,5.535
3.52737,0.07055,0.30434,5.546
3.54413,0.07088,0.30560,5.535
3.56123,0.07122,0.30703,5.551
3.57836,0.07157,0.30838,5.546
3.59544,0.07191,0.30973,5.563
3.61214,0.07224,0.31113,5.570
3.62932,0.07259,0.31248,5.568
3.64574,0.07291,0.31383,5.576
3.66275,0.07326,0.31519,5.572
3.67937,0.07359,0.31656,5.579
3.69602,0.07392,0.31796,5.581
3.71261,0.07425,0.31926,5.585
3.72906,0.07458,0.32062,5.600
3.74593,0.07492,0.32199,5.589
3.76160,0.07523,0.32335,5.593
3.77795,0.07556,0.32469,5.596
3.79489,0.07590,0.32607,5.604
3.81101,0.07622,0.32735,5.610
3.82724,0.07654,0.32872,5.602
3.84363,0.07687,0.33001,5.614
3.86010,0.07720,0.33142,5.623
3.87658,0.07753,0.33275,5.618
3.89285,0.07786,0.33406,5.626
3.90902,0.07818,0.33539,5.622
3.92546,0.07851,0.33674,5.630
3.94173,0.07883,0.33806,5.629
3.95787,0.07916,0.33932,5.629
3.97385,0.07948,0.34066,5.645
3.99002,0.07980,0.34190,5.630
4.00595,0.08012,0.34320,5.649
4.02169,0.08043,0.34446,5.642
4.03742,0.08075,0.34570,5.650
4.05340,0.08107,0.34695,5.649
4.06926,0.08139,0.34820,5.649
4.08471,0.08169,0.34945,5.652
4.10055,0.08201,0.35071,5.659
4.11583,0.08232,0.35199,5.666
4.13150,0.08263,0.35321,5.664
4.14709,0.08294,0.35443,5.659
4.16242,0.08325,0.35565,5.673
4.17795,0.08356,0.35681,5.672
4.19327,0.08387,0.35799,5.680
4.20840,0.08417,0.35922,5.679
4.22342,0.08447,0.36043,5.681
4.23874,0.08477,0.36162,5.681
4.25399,0.08508,0.36288,5.684
4.26935,0.08539,0.36405,5.690
4.28410,0.08568,0.36531,5.680
4.29893,0.08598,0.36646,5.695
4.31353,0.08627,0.36761,5.691
4.32834,0.08657,0.36877,5.692
4.34244,0.08685,0.36994,5.692
4.35736,0.08715,0.37110,5.697
4.37176,0.08744,0.37229,5.707
4.38617,0.08772,0.37341,5.705
4.40075,0.08802,0.37461,5.701
4.41523,0.08830,0.37569,5.715
4.42961,0.08859,0.37680,5.712
4.44385,0.08888,0.37795,5.709
4.45800,0.08916,0.37912,5.722
4.47199,0.08944,0.38020,5.710
4.48612,0.08972,0.38137,5.724
4.50038,0.09001,0.38242,5.727
4.51417,0.09028,0.38357,5.725
4.52820,0.09056,0.38463,5.728
4.54200,0.09084,0.38573,5.729
4.55584,0.09112,0.38686,5.736
4.57002,0.09140,0.38795,5.727
4.58389,0.09168,0.38907,5.742
4.59742,0.09195,0.39018,5.741
4.61118,0.09222,0.39126,5.737
4.62509,0.09250,0.39236,5.748
4.63899,0.09278,0.39346,5.735
4.65292,0.09306,0.39454,5.751
4.66698,0.09334,0.39562,5.753
4.68086,0.09362,0.39671,5.754
4.69434,0.09389,0.39785,5.765
4.70804,0.09416,0.39886,5.750
4.72173,0.09443,0.39998,5.762
4.73521,0.09470,0.40107,5.753
4.74869,0.09497,0.40211,5.747
4.76231,0.09525,0.40321,5.769
4.77552,0.09551,0.40426,5.754
4.78872,0.09577,0.40530,5.767
4.80172,0.09603,0.40631,5.761
4.81466,0.09629,0.40731,5.772
4.82763,0.09655,0.40837,5.772
4.84092,0.09682,0.40940,5.768
4.85376,0.09708,0.41042,5.772
4.86626,0.09733,0.41140,5.754
4.87936,0.09759,0.41242,5.775
4.89218,0.09784,0.41342,5.776
4.90500,0.09810,0.41443,5.771
4.91783,0.09836,0.41545,5.775
4.93106,0.09862,0.41643,5.771
4.94363,0.09887,0.41742,5.777
4.95607,0.09912,0.41838,5.785
4.96880,0.09938,0.41938,5.771
4.98113,0.09962,0.42032,5.783
4.99370,0.09987,0.42132,5.786
5.00611,0.10012,0.42228,5.789
5.01831,0.10037,0.42325,5.785
5.03059,0.10061,0.42416,5.785
5.04293,0.10086,0.42519,5.796
5.05488,0.10110,0.42616,5.784
5.06715,0.10134,0.42704,5.795
5.07921,0.10158,0.42798,5.792
5.09167,0.10183,0.42892,5.788
5.10385,0.10208,0.42987,5.792
5.11587,0.10232,0.43079,5.790
5.12793,0.10256,0.43180,5.801
5.13998,0.10280,0.43275,5.806
5.15217,0.10304,0.43367,5.796
5.16382,0.10328,0.43463,5.811
5.17548,0.10351,0.43547,5.797
5.18757,0.10375,0.43640,5.805
5.19906,0.10398,0.43730,5.812
5.21056,0.10421,0.43819,5.805
5.22243,0.10445,0.43911,5.806
5.23377,0.10468,0.43996,5.805
5.24500,0.10490,0.44088,5.808
5.25669,0.10513,0.44174,5.812
5.26820,0.10536,0.44265,5.811
5.27981,0.10560,0.44354,5.822
5.29118,0.10582,0.44442,5.812
5.30244,0.10605,0.44530,5.820
5.31319,0.10626,0.44620,5.813
5.32477,0.10650,0.44709,5.811
5.33602,0.10672,0.44791,5.828
5.34773,0.10695,0.44886,5.814
5.35876,0.10718,0.44974,5.824
5.37021,0.10740,0.45065,5.821
5.38147,0.10763,0.45156,5.822
5.39251,0.10785,0.45246,5.830
5.40410,0.10808,0.45331,5.816
5.41529,0.10831,0.45426,5.826
5.42666,0.10853,0.45511,5.824
5.43780,0.10876,0.45604,5.834
5.44937,0.10899,0.45691,5.837
5.46073,0.10921,0.45777,5.830
5.47197,0.10944,0.45863,5.842
5.48303,0.10966,0.45947,5.831
5.49459,0.10989,0.46040,5.840
5.50543,0.11011,0.46132,5.838
5.51690,0.11034,0.46221,5.827
5.52799,0.11056,0.46311,5.840
5.53942,0.11079,0.46399,5.837
5.55051,0.11101,0.46485,5.837
5.56165,0.11123,0.46572,5.849
5.57252,0.11145,0.46659,5.834
5.58356,0.11167,0.46750,5.852
5.59493,0.11190,0.46838,5.843
5.60635,0.11213,0.46921,5.846
5.61743,0.11235,0.47014,5.845
5.62865,0.11257,0.47097,5.843
5.63950,0.11279,0.47184,5.855
5.65065,0.11301,0.47274,5.842
5.66187,0.11324,0.47357,5.853
5.67323,0.11346,0.47447,5.860
5.68457,0.11369,0.47529,5.856
5.69561,0.11391,0.47611,5.858
5.70677,0.11414,0.47702,5.850
5.71763,0.11435,0.47791,5.843
5.72863,0.11457,0.47874,5.860
5.73974,0.11479,0.47964,5.843
5.75083,0.11502,0.48050,5.855
5.76158,0.11523,0.48130,5.855
5.77257,0.11545,0.48220,5.865
5.78377,0.11568,0.48306,5.859
5.79483,0.11590,0.48395,5.858
5.80587,0.11612,0.48479,5.869
5.81683,0.11634,0.48567,5.869
5.82749,0.11655,0.48649,5.859
5.83823,0.11676,0.48736,5.865
5.84928,0.11699,0.48818,5.860
5.86027,0.11721,0.48910,5.873
5.87140,0.11743,0.48993,5.866
5.88249,0.11765,0.49081,5.861
5.89299,0.11786,0.49163,5.867
5.90441,0.11809,0.49250,5.867
5.91528,0.11831,0.49344,5.872
5.92626,0.11853,0.49427,5.867
5.93737,0.11875,0.49511,5.876
5.94811,0.11896,0.49595,5.880
5.95946,0.11919,0.49681,5.868
5.97050,0.11941,0.49769,5.881
5.98163,0.11963,0.49849,5.878
5.99289,0.11986,0.49935,5.880
6.00353,0.12007,0.50024,5.881
6.01474,0.12029,0.50101,5.874
6.02528,0.12051,0.50191,5.880
6.03642,0.12073,0.50276,5.880
6.04763,0.12095,0.50363,5.875
6.05860,0.12117,0.50446,5.883
6.06949,0.12139,0.50527,5.881
6.08052,0.12161,0.50617,5.884
6.09121,0.12182,0.50705,5.879
6.10231,0.12205,0.50792,5.879
6.11328,0.12227,0.50876,5.881
6.12410,0.12248,0.50959,5.885
6.13517,0.12270,0.51042,5.887
6.14645,0.12293,0.51124,5.880
6.15711,0.12314,0.51209,5.883
6.16812,0.12336,0.51297,5.887
6.17924,0.12358,0.51384,5.884
6.19053,0.12381,0.51464,5.895
6.20145,0.12403,0.51545,5.891
6.21256,0.12425,0.51625,5.888
6.22384,0.12448,0.51711,5.892
6.23497,0.12470,0.51791,5.890
6.24602,0.12492,0.51877,5.891
6.25741,0.12515,0.51960,5.885
6.26852,0.12537,0.52044,5.889
6.27951,0.12559,0.52127,5.901
6.29071,0.12581,0.52212,5.897
6.30194,0.12604,0.52296,5.899
6.31338,0.12627,0.52381,5.900
6.32436,0.12649,0.52462,5.893
6.33567,0.12671,0.52548,5.901
6.34656,0.12693,0.52630,5.897
6.35747,0.12715,0.52718,5.898
6.36870,0.12737,0.52798,5.900
6.38003,0.12760,0.52879,5.894
6.39124,0.12782,0.52962,5.900
6.40258,0.12805,0.53050,5.901
6.41355,0.12827,0.53134,5.904
6.42467,0.12849,0.53215,5.903
6.43622,0.12872,0.53299,5.896
6.44738,0.12895,0.53382,5.907
6.45867,0.12917,0.53466,5.901
6.46999,0.12940,0.53549,5.909
6.48149,0.12963,0.53639,5.905
6.49278,0.12986,0.53721,5.906
6.50450,0.13009,0.53808,5.912
6.51554,0.13031,0.53892,5.909
6.52716,0.13054,0.53977,5.919
6.53866,0.13077,0.54063,5.906
6.54978,0.13100,0.54149,5.908
6.56100,0.13122,0.54236,5.913
6.57274,0.13145,0.54323,5.907
6.58420,0.13168,0.54409,5.916
6.59569,0.13191,0.54495,5.917
6.60684,0.13214,0.54579,5.915
6.61818,0.13236,0.54663,5.920
6.62967,0.13259,0.54748,5.913
6.64110,0.13282,0.54837,5.915
6.65301,0.13306,0.54924,5.916
6.66460,0.13329,0.55010,5.916
6.67575,0.13351,0.55097,5.923
6.68724,0.13374,0.55185,5.913
6.69908,0.13398,0.55273,5.923
6.71058,0.13421,0.55358,5.920
6.72208,0.13444,0.55441,5.916
6.73402,0.13468,0.55533,5.925
6.74600,0.13492,0.55618,5.925
6.75742,0.13515,0.55711,5.928
6.76909,0.13538,0.55796,5.921
6.78083,0.13562,0.55881,5.925
6.79268,0.13585,0.55968,5.927
6.80409,0.13608,0.56048,5.927
6.81584,0.13632,0.56139,5.927
6.82754,0.13655,0.56227,5.922
6.83936,0.13679,0.56311,5.926
6.85120,0.13702,0.56399,5.923
6.86265,0.13725,0.56486,5.928
6.87391,0.13748,0.56569,5.934
6.88604,0.13772,0.56664,5.924
6.89792,0.13796,0.56751,5.929
6.90946,0.13819,0.56839,5.929
6.92144,0.13843,0.56918,5.924
6.93294,0.13866,0.57010,5.932
6.94479,0.13890,0.57097,5.929
6.95668,0.13913,0.57181,5.932
6.96836,0.13937,0.57264,5.929
6.98027,0.13961,0.57350,5.925
6.99204,0.13984,0.57435,5.933
7.00397,0.14008,0.57515,5.932
7.01602,0.14032,0.57603,5.934
7.02789,0.14056,0.57688,5.943
7.03982,0.14080,0.57777,5.926
7.05181,0.14104,0.57859,5.938
7.06350,0.14127,0.57941,5.937
7.07578,0.14152,0.58027,5.944
7.08774,0.14175,0.58113,5.939
7.09971,0.14199,0.58198,5.926
7.11163,0.14223,0.58284,5.936
7.12344,0.14247,0.58369,5.931
7.13558,0.14271,0.58456,5.937
7.14768,0.14295,0.58540,5.941
7.15957,0.14319,0.58624,5.943
7.17171,0.14343,0.58717,5.941
7.18362,0.14367,0.58797,5.937
7.19540,0.14391,0.58887,5.939
7.20754,0.14415,0.58976,5.943
7.21978,0.14440,0.59060,5.946
7.23192,0.14464,0.59150,5.944
7.24401,0.14488,0.59234,5.939
7.25618,0.14512,0.59312,5.944
7.26846,0.14537,0.59409,5.944
7.28057,0.14561,0.59492,5.940
7.29253,0.14585,0.59577,5.946
7.30478,0.14610,0.59662,5.942
7.31695,0.14634,0.59745,5.946
7.32884,0.14658,0.59832,5.953
7.34145,0.14683,0.59910,5.942
7.35356,0.14707,0.60001,5.949
7.36631,0.14733,0.60081,5.944
7.37843,0.14757,0.60164,5.940
7.38995,0.14780,0.60256,5.945
7.40243,0.14805,0.60340,5.947
7.41511,0.14830,0.60431,5.952
7.42735,0.14855,0.60524,5.942
7.44000,0.14880,0.60610,5.951
7.45177,0.14904,0.60700,5.951
7.46447,0.14929,0.60787,5.944
7.47687,0.14954,0.60871,5.949
7.48929,0.14979,0.60958,5.942
7.50196,0.15004,0.61046,5.946
7.51446,0.15029,0.61130,5.960
7.52725,0.15055,0.61219,5.951
7.53982,0.15080,0.61307,5.954
7.55256,0.15105,0.61393,5.951
7.56498,0.15130,0.61488,5.947
7.57756,0.15155,0.61573,5.954
7.59039,0.15181,0.61661,5.948
7.60295,0.15206,0.61758,5.956
7.61568,0.15231,0.61846,5.949
7.62841,0.15257,0.61940,5.952
7.64089,0.15282,0.62036,5.956
7.65372,0.15307,0.62122,5.944
7.66672,0.15333,0.62214,5.959
7.67934,0.15359,0.62306,5.954
7.69206,0.15384,0.62396,5.956
7.70474,0.15409,0.62485,5.963
7.71769,0.15435,0.62572,5.946
7.73068,0.15461,0.62662,5.955
7.74345,0.15487,0.62755,5.950
7.75642,0.15513,0.62848,5.959
7.76961,0.15539,0.62939,5.961
7.78265,0.15565,0.63034,5.960
7.79590,0.15592,0.63126,5.962
7.80893,0.15618,0.63215,5.957
7.82177,0.15644,0.63311,5.964
7.83477,0.15670,0.63405,5.961
7.84751,0.15695,0.63499,5.963
7.86073,0.15721,0.63603,5.965
7.87398,0.15748,0.63697,5.963
7.88720,0.15774,0.63793,5.963
7.89978,0.15800,0.63888,5.967
7.91279,0.15826,0.63983,5.964
7.92617,0.15852,0.64072,5.975
7.93910,0.15878,0.64166,5.963
7.95244,0.15905,0.64261,5.966
7.96563,0.15931,0.64358,5.971
7.97857,0.15957,0.64450,5.957
7.99185,0.15984,0.64542,5.959
8.00538,0.16011,0.64637,5.962
8.01863,0.16037,0.64731,5.972
8.03213,0.16064,0.64830,5.971
8.04557,0.16091,0.64921,5.959
8.05907,0.16118,0.65012,5.971
8.07242,0.16145,0.65113,5.961
8.08608,0.16172,0.65205,5.968
8.09910,0.16198,0.65305,5.965
8.11282,0.16226,0.65402,5.963
8.12644,0.16253,0.65497,5.964
8.14008,0.16280,0.65595,5.961
8.15359,0.16307,0.65693,5.967
8.16667,0.16333,0.65786,5.960
8.18040,0.16361,0.65884,5.963
8.19393,0.16388,0.65983,5.966
8.20767,0.16415,0.66077,5.960
8.22090,0.16442,0.66176,5.973
8.23465,0.16469,0.66274,5.960
8.24820,0.16496,0.66370,5.967
8.26184,0.16524,0.66467,5.974
8.27567,0.16551,0.66567,5.968
8.28935,0.16579,0.66668,5.967
8.30330,0.16607,0.66765,5.969
8.31679,0.16634,0.66864,5.972
8.33062,0.16661,0.66962,5.975
8.34413,0.16688,0.67058,5.971
8.35775,0.16716,0.67156,5.972
8.37144,0.16743,0.67252,5.966
8.38529,0.16771,0.67351,5.970
8.39909,0.16798,0.67443,5.972
8.41308,0.16826,0.67538,5.970
8.42648,0.16853,0.67635,5.979
8.44021,0.16880,0.67730,5.967
8.45441,0.16909,0.67824,5.982
8.46830,0.16937,0.67919,5.978
8.48200,0.16964,0.68013,5.973
8.49542,0.16991,0.68113,5.982
8.50960,0.17019,0.68206,5.966
8.52381,0.17048,0.68307,5.978
8.53764,0.17075,0.68401,5.968
8.55222,0.17104,0.68498,5.977
8.56611,0.17132,0.68592,5.969
8.58038,0.17161,0.68690,5.966
8.59440,0.17189,0.68786,5.978
8.60847,0.17217,0.68882,5.973
8.62229,0.17245,0.68978,5.975
8.63662,0.17273,0.69077,5.981
8.65077,0.17302,0.69175,5.973
8.66475,0.17330,0.69276,5.977
8.67855,0.17357,0.69373,5.970
8.69246,0.17385,0.69472,5.977
8.70668,0.17413,0.69571,5.978
8.72106,0.17442,0.69664,5.973
8.73498,0.17470,0.69766,5.982
8.74906,0.17498,0.69866,5.975
8.76307,0.17526,0.69964,5.984
8.77734,0.17555,0.70061,5.980
8.79165,0.17583,0.70160,5.980
8.80601,0.17612,0.70266,5.984
8.82028,0.17641,0.70365,5.976
8.83454,0.17669,0.70467,5.987
8.84890,0.17698,0.70571,5.979
8.86306,0.17726,0.70666,5.984
8.87744,0.17755,0.70766,5.980
8.89187,0.17784,0.70869,5.976
8.90603,0.17812,0.70973,5.985
8.92056,0.17841,0.71065,5.978
8.93471,0.17869,0.71164,5.984
8.94859,0.17897,0.71258,5.984
8.96343,0.17927,0.71352,5.978
8.97757,0.17955,0.71455,5.990
8.99227,0.17985,0.71547,5.976
9.00639,0.18013,0.71651,5.985
9.02073,0.18041,0.71745,5.978
9.03563,0.18071,0.71844,5.982
9.04991,0.18100,0.71949,5.982
9.06458,0.18129,0.72041,5.973
9.07916,0.18158,0.72143,5.987
9.09372,0.18187,0.72240,5.972
9.10809,0.18216,0.72335,5.979
9.12266,0.18245,0.72437,5.983
9.13713,0.18274,0.72533,5.980
9.15184,0.18304,0.72635,5.982
9.16632,0.18333,0.72731,5.975
9.18089,0.18362,0.72836,5.982
9.19524,0.18390,0.72936,5.973
9.20958,0.18419,0.73039,5.976
9.22458,0.18449,0.73138,5.979
9.23919,0.18478,0.73235,5.975
9.25356,0.18507,0.73333,5.984
9.26810,0.18536,0.73435,5.979
9.28305,0.18566,0.73532,5.979
9.29751,0.18595,0.73631,5.977
9.31203,0.18624,0.73728,5.978
9.32717,0.18654,0.73825,5.982
9.34163,0.18683,0.73930,5.979
9.35639,0.18713,0.74027,5.980
9.37133,0.18743,0.74122,5.978
9.38617,0.18772,0.74223,5.977
9.40029,0.18801,0.74322,5.981
9.41518,0.18830,0.74416,5.972
9.43000,0.18860,0.74520,5.987
9.44453,0.18889,0.74621,5.977
9.45896,0.18918,0.74718,5.984
9.47364,0.18947,0.74816,5.976
9.48861,0.18977,0.74915,5.976
9.50340,0.19007,0.75017,5.974
9.51789,0.19036,0.75109,5.971
9.53252,0.19065,0.75208,5.985
9.54732,0.19095,0.75303,5.972
9.56211,0.19124,0.75403,5.981
9.57710,0.19154,0.75498,5.975
9.59223,0.19184,0.75594,5.979
9.60689,0.19214,0.75694,5.980
9.62162,0.19243,0.75794,5.975
9.63655,0.19273,0.75894,5.983
9.65101,0.19302,0.75991,5.973
9.66595,0.19332,0.76090,5.986
9.68014,0.19360,0.76189,5.978
9.69513,0.19390,0.76284,5.973
9.71003,0.19420,0.76384,5.979
9.72423,0.19448,0.76476,5.969
9.73909,0.19478,0.76578,5.983
9.75376,0.19508,0.76670,5.970
9.76879,0.19538,0.76771,5.972
9.78303,0.19566,0.76871,5.974
9.79809,0.19596,0.76969,5.974
9.81277,0.19626,0.77067,5.978
9.82747,0.19655,0.77167,5.968
9.84250,0.19685,0.77269,5.981
9.85759,0.19715,0.77369,5.975
9.87225,0.19745,0.77465,5.977
9.88707,0.19774,0.77564,5.977
9.90204,0.19804,0.77653,5.971
9.91644,0.19833,0.77754,5.985
9.93156,0.19863,0.77846,5.967
9.94624,0.19892,0.77944,5.980
9.96127,0.19923,0.78036,5.977
9.97563,0.19951,0.78129,5.975
9.99063,0.19981,0.78228,5.982
10.00568,0.20011,0.78323,5.971
10.02060,0.20041,0.78420,5.977
10.03529,0.20071,0.78511,5.970
10.04988,0.20100,0.78612,5.978
10.06480,0.20130,0.78706,5.975
10.08007,0.20160,0.78801,5.979
10.09487,0.20190,0.78897,5.972
10.11012,0.20220,0.78989,5.970
10.12511,0.20250,0.79087,5.972
10.14018,0.20280,0.79178,5.976
10.15549,0.20311,0.79276,5.976
10.16988,0.20340,0.79371,5.973
10.18512,0.20370,0.79465,5.978
10.20009,0.20400,0.79562,5.973
10.21528,0.20431,0.79655,5.964
10.23011,0.20460,0.79749,5.973
10.24463,0.20489,0.79843,5.966
10.25990,0.20520,0.79938,5.970
10.27479,0.20550,0.80033,5.977
10.28991,0.20580,0.80124,5.960
10.30442,0.20609,0.80217,5.968
10.31944,0.20639,0.80306,5.968
10.33409,0.20668,0.80400,5.974
10.34933,0.20699,0.80491,5.965
10.36464,0.20729,0.80588,5.971
10.37932,0.20759,0.80674,5.967
10.39445,0.20789,0.80761,5.969
10.40907,0.20818,0.80859,5.968
10.42422,0.20848,0.80945,5.966
10.43890,0.20878,0.81041,5.978
10.45381,0.20908,0.81127,5.968
10.46887,0.20938,0.81225,5.968
10.48399,0.20968,0.81310,5.966
10.49856,0.20997,0.81405,5.971
10.51313,0.21026,0.81490,5.974
10.52833,0.21057,0.81577,5.964
10.54324,0.21086,0.81668,5.966
10.55776,0.21116,0.81759,5.968
10.57305,0.21146,0.81849,5.968
10.58805,0.21176,0.81939,5.962
10.60301,0.21206,0.82024,5.962
10.61791,0.21236,0.82112,5.971
10.63310,0.21266,0.82203,5.962
10.64814,0.21296,0.82297,5.966
10.66307,0.21326,0.82382,5.961
10.67824,0.21356,0.82467,5.965
10.69293,0.21386,0.82559,5.966
10.70804,0.21416,0.82644,5.953
10.72295,0.21446,0.82738,5.961
10.73807,0.21476,0.82825,5.960
10.75280,0.21506,0.82909,5.966
10.76775,0.21535,0.82999,5.957
10.78281,0.21566,0.83084,5.961
10.79774,0.21595,0.83171,5.964
10.81263,0.21625,0.83261,5.956
10.82765,0.21655,0.83346,5.961
10.84267,0.21685,0.83430,5.949
10.85767,0.21715,0.83521,5.962
10.87267,0.21745,0.83604,5.950
10.88806,0.21776,0.83691,5.955
10.90300,0.21806,0.83778,5.958
10.91815,0.21836,0.83863,5.951
10.93311,0.21866,0.83954,5.952
10.94794,0.21896,0.84046,5.955
10.96282,0.21926,0.84129,5.961
10.97777,0.21956,0.84212,5.952
10.99250,0.21985,0.84298,5.949
11.00739,0.22015,0.84381,5.948
11.02176,0.22044,0.84463,5.950
11.03682,0.22074,0.84545,5.960
11.05184,0.22104,0.84625,5.948
11.06658,0.22133,0.84703,5.957
11.08129,0.22163,0.84783,5.953
11.09617,0.22192,0.84856,5.951
11.11145,0.22223,0.84941,5.952
11.12595,0.22252,0.85012,5.947
11.14115,0.22282,0.85092,5.950
11.15613,0.22312,0.85165,5.941
11.17081,0.22342,0.85238,5.945
11.18583,0.22372,0.85315,5.951
11.20073,0.22401,0.85394,5.948
11.21548,0.22431,0.85466,5.945
11.23032,0.22461,0.85543,5.943
11.24499,0.22490,0.85613,5.948
11.25996,0.22520,0.85687,5.937
11.27429,0.22549,0.85758,5.945
11.28920,0.22578,0.85832,5.933
11.30385,0.22608,0.85900,5.942
11.31861,0.22637,0.85965,5.942
11.33327,0.22667,0.86034,5.938
11.34767,0.22695,0.86105,5.952
11.36236,0.22725,0.86163,5.936
11.37695,0.22754,0.86236,5.943
11.39184,0.22784,0.86294,5.934
11.40661,0.22813,0.86363,5.939
11.42077,0.22842,0.86428,5.939
11.43565,0.22871,0.86484,5.932
11.45017,0.22900,0.86546,5.940
11.46443,0.22929,0.86604,5.930
11.47870,0.22957,0.86667,5.938
11.49356,0.22987,0.86730,5.935
11.50787,0.23016,0.86784,5.926
11.52249,0.23045,0.86843,5.929
11.53649,0.23073,0.86901,5.924
11.55068,0.23101,0.86958,5.930
11.56518,0.23130,0.87015,5.923
11.57980,0.23160,0.87074,5.923
11.59403,0.23188,0.87130,5.920
11.60837,0.23217,0.87184,5.924
11.62266,0.23245,0.87237,5.925
11.63738,0.23275,0.87288,5.916
11.65172,0.23303,0.87348,5.924
11.66626,0.23333,0.87397,5.918
11.68041,0.23361,0.87450,5.917
11.69519,0.23390,0.87496,5.914
11.70939,0.23419,0.87547,5.917
11.72318,0.23446,0.87597,5.918
11.73765,0.23475,0.87650,5.911
11.75207,0.23504,0.87695,5.921
11.76633,0.23533,0.87739,5.906
11.78068,0.23561,0.87780,5.908
11.79461,0.23589,0.87822,5.904
11.80877,0.23618,0.87865,5.914
11.82302,0.23646,0.87901,5.900
11.83729,0.23675,0.87944,5.900
11.85113,0.23702,0.87984,5.903
11.86515,0.23730,0.88021,5.903
11.87947,0.23759,0.88061,5.903
11.89323,0.23786,0.88092,5.896
11.90763,0.23815,0.88135,5.903
11.92184,0.23844,0.88167,5.896
11.93592,0.23872,0.88201,5.898
11.95017,0.23900,0.88236,5.901
11.96416,0.23928,0.88261,5.882
11.97798,0.23956,0.88298,5.893
11.99148,0.23983,0.88327,5.883
12.00565,0.24011,0.88355,5.888
12.01955,0.24039,0.88384,5.885
12.03372,0.24067,0.88410,5.881
12.04709,0.24094,0.88435,5.885
12.06069,0.24121,0.88460,5.878
12.07452,0.24149,0.88485,5.880
12.08851,0.24177,0.88498,5.873
12.10237,0.24205,0.88523,5.878
12.11599,0.24232,0.88542,5.876
12.12994,0.24260,0.88561,5.870
12.14388,0.24288,0.88583,5.878
12.15736,0.24315,0.88594,5.858
12.17118,0.24342,0.88616,5.863
12.18516,0.24370,0.88630,5.850
12.19894,0.24398,0.88647,5.860
12.21256,0.24425,0.88657,5.852
12.22630,0.24453,0.88671,5.852
12.23975,0.24479,0.88685,5.855
12.25345,0.24507,0.88693,5.838
12.26647,0.24533,0.88708,5.843
12.28009,0.24560,0.88714,5.834
12.29308,0.24586,0.88724,5.838
12.30624,0.24612,0.88730,5.830
12.31912,0.24638,0.88739,5.829
12.33241,0.24665,0.88751,5.823
12.34532,0.24691,0.88752,5.814
12.35851,0.24717,0.88762,5.824
12.37135,0.24743,0.88760,5.808
12.38427,0.24769,0.88779,5.808
12.39756,0.24795,0.88776,5.803
12.41064,0.24821,0.88780,5.800
12.42346,0.24847,0.88788,5.802
12.43680,0.24874,0.88785,5.786
12.44982,0.24900,0.88792,5.795
12.46279,0.24926,0.88794,5.780
12.47558,0.24951,0.88798,5.780
12.48849,0.24977,0.88801,5.768
12.50126,0.25003,0.88800,5.773
12.51386,0.25028,0.88811,5.764
12.52698,0.25054,0.88804,5.755
12.53967,0.25079,0.88808,5.755
12.55227,0.25105,0.88805,5.742
12.56489,0.25130,0.88810,5.757
12.57742,0.25155,0.88804,5.735
12.58983,0.25180,0.88809,5.731
12.60244,0.25205,0.88812,5.720
12.61493,0.25230,0.88808,5.718
12.62729,0.25255,0.88808,5.714
12.63997,0.25280,0.88802,5.699
12.65200,0.25304,0.88811,5.701
12.66438,0.25329,0.88804,5.682
12.67681,0.25354,0.88804,5.681
12.68898,0.25378,0.88811,5.672
12.70170,0.25403,0.88807,5.660
12.71372,0.25427,0.88808,5.670
12.72622,0.25452,0.88803,5.648
12.73874,0.25477,0.88807,5.649
12.75100,0.25502,0.88801,5.634
12.76287,0.25526,0.88800,5.631
12.77492,0.25550,0.88804,5.624
12.78738,0.25575,0.88795,5.611
12.79911,0.25598,0.88797,5.601
12.81126,0.25623,0.88786,5.583
12.82310,0.25646,0.88794,5.579
12.83496,0.25670,0.88790,5.571
12.84690,0.25694,0.88789,5.559
12.85881,0.25718,0.88790,5.542
12.87117,0.25742,0.88778,5.528
12.88242,0.25765,0.88792,5.526
12.89502,0.25790,0.88772,5.507
12.90663,0.25813,0.88781,5.505
12.91880,0.25838,0.88779,5.479
12.93116,0.25862,0.88753,5.470
12.94260,0.25885,0.88787,5.454
12.95550,0.25911,0.88761,5.426
12.96742,0.25935,0.88754,5.422
12.97861,0.25957,0.88783,5.399
12.99172,0.25983,0.88748,5.392
13.00375,0.26007,0.88747,5.362
13.01565,0.26031,0.88748,5.348
13.02753,0.26055,0.88744,5.328