File: fss/tension_R15.txt
""
"Test Method","Tensile_R_yu.msm"
"Sample I. D.","10-1-304TD1 Hyunjin.mss"
"Specimen Number","8"

"Extension (mm)","Extensometer_A (mm/mm)","Extensometer_T (mm)","Load (kN)"

-0.00012,0.00000,0.00007,0.005
0.00007,0.00000,0.00008,0.020
0.00045,0.00001,0.00010,0.047
0.00081,0.00002,0.00016,0.070
0.00122,0.00002,0.00022,0.116
0.00198,0.00004,0.00035,0.164
0.00296,0.00006,0.00054,0.232
0.00437,0.00009,0.00065,0.319
0.00635,0.00013,0.00086,0.414
0.00861,0.00017,0.00112,0.547
0.01131,0.00023,0.00134,0.689
0.01459,0.00029,0.00165,0.852
0.01882,0.00038,0.00202,1.028
0.02308,0.00046,0.00239,1.226
0.02809,0.00056,0.00278,1.453
0.03356,0.00067,0.00323,1.693
0.03970,0.00079,0.00369,1.958
0.04669,0.00093,0.00425,2.223
0.05454,0.00109,0.00484,2.493
0.06297,0.00126,0.00553,2.724
0.07258,0.00145,0.00639,2.935
0.08404,0.00168,0.00750,3.116
0.09688,0.00194,0.00891,3.233
0.11206,0.00224,0.01072,3.311
0.12852,0.00257,0.01277,3.366
0.14692,0.00294,0.01512,3.405
0.16686,0.00334,0.01761,3.431
0.18722,0.00374,0.02015,3.443
0.20920,0.00418,0.02289,3.455
0.23208,0.00464,0.02565,3.465
0.25556,0.00511,0.02858,3.489
0.28018,0.00560,0.03161,3.507
0.30513,0.00610,0.03469,3.524
0.33070,0.00661,0.03779,3.553
0.35678,0.00714,0.04102,3.570
0.38340,0.00767,0.04440,3.604
0.41043,0.00821,0.04774,3.614
0.43793,0.00876,0.05125,3.633
0.46635,0.00933,0.05477,3.651
0.49494,0.00990,0.05834,3.671
0.52379,0.01048,0.06190,3.690
0.55317,0.01106,0.06562,3.714
0.58328,0.01167,0.06929,3.742
0.61347,0.01227,0.07295,3.768
0.64395,0.01288,0.07675,3.786
0.67488,0.01350,0.08061,3.808
0.70532,0.01411,0.08444,3.840
0.73682,0.01474,0.08834,3.859
0.76845,0.01537,0.09239,3.885
0.80039,0.01601,0.09638,3.902
0.83325,0.01666,0.10049,3.917
0.86609,0.01732,0.10463,3.952
0.89856,0.01797,0.10875,3.974
0.93184,0.01864,0.11284,4.000
0.96502,0.01930,0.11701,4.025
0.99871,0.01997,0.12124,4.049
1.03215,0.02064,0.12539,4.074
1.06616,0.02132,0.12963,4.092
1.10048,0.02201,0.13386,4.115
1.13496,0.02270,0.13805,4.133
1.16916,0.02338,0.14231,4.153
1.20359,0.02407,0.14652,4.176
1.23775,0.02476,0.15078,4.191
1.27201,0.02544,0.15493,4.207
1.30644,0.02613,0.15918,4.237
1.34175,0.02683,0.16336,4.253
1.37697,0.02754,0.16773,4.277
1.41190,0.02824,0.17218,4.293
1.44776,0.02896,0.17651,4.323
1.48263,0.02965,0.18080,4.337
1.51787,0.03036,0.18520,4.360
1.55322,0.03106,0.18953,4.384
1.58859,0.03177,0.19387,4.405
1.62405,0.03248,0.19816,4.410
1.65962,0.03319,0.20254,4.427
1.69461,0.03389,0.20691,4.457
1.73007,0.03460,0.21114,4.474
1.76483,0.03530,0.21542,4.489
1.80006,0.03600,0.21976,4.508
1.83542,0.03671,0.22403,4.516
1.87085,0.03742,0.22831,4.530
1.90601,0.03812,0.23258,4.543
1.94089,0.03882,0.23682,4.569
1.97593,0.03952,0.24108,4.584
2.01050,0.04021,0.24546,4.599
2.04565,0.04091,0.24974,4.611
2.08056,0.04161,0.25402,4.623
2.11570,0.04231,0.25821,4.641
2.15075,0.04302,0.26242,4.662
2.18538,0.04371,0.26664,4.670
2.22005,0.04440,0.27078,4.683
2.25440,0.04509,0.27487,4.687
2.28911,0.04578,0.27905,4.717
2.32352,0.04647,0.28323,4.730
2.35804,0.04716,0.28728,4.746
2.39279,0.04786,0.29135,4.755
2.42737,0.04855,0.29551,4.761
2.46154,0.04923,0.29968,4.771
2.49586,0.04992,0.30375,4.787
2.52970,0.05059,0.30785,4.800
2.56441,0.05129,0.31180,4.817
2.59846,0.05197,0.31578,4.838
2.63261,0.05265,0.31967,4.840
2.66731,0.05335,0.32367,4.856
2.70107,0.05402,0.32759,4.864
2.73518,0.05470,0.33159,4.870
2.76848,0.05537,0.33567,4.879
2.80250,0.05605,0.33959,4.890
2.83598,0.05672,0.34362,4.895
2.86987,0.05740,0.34759,4.912
2.90430,0.05809,0.35152,4.920
2.93835,0.05877,0.35534,4.934
2.97233,0.05945,0.35923,4.943
3.00618,0.06012,0.36310,4.960
3.03947,0.06079,0.36703,4.957
3.07306,0.06146,0.37098,4.970
3.10652,0.06213,0.37490,4.975
3.13984,0.06280,0.37882,4.990
3.17321,0.06346,0.38269,4.997
3.20679,0.06414,0.38667,5.007
3.23984,0.06480,0.39049,5.016
3.27345,0.06547,0.39437,5.030
3.30633,0.06613,0.39818,5.041
3.33956,0.06679,0.40195,5.044
3.37294,0.06746,0.40566,5.059
3.40634,0.06813,0.40945,5.047
3.43962,0.06879,0.41326,5.064
3.47279,0.06946,0.41704,5.072
3.50502,0.07010,0.42084,5.078
3.53788,0.07076,0.42462,5.085
3.57022,0.07140,0.42836,5.099
3.60314,0.07206,0.43210,5.099
3.63553,0.07271,0.43582,5.114
3.66833,0.07337,0.43950,5.118
3.70119,0.07402,0.44314,5.131
3.73356,0.07467,0.44684,5.126
3.76582,0.07532,0.45052,5.139
3.79808,0.07596,0.45426,5.145
3.82949,0.07659,0.45788,5.145
3.86141,0.07723,0.46156,5.168
3.89295,0.07786,0.46521,5.170
3.92512,0.07850,0.46882,5.179
3.95709,0.07914,0.47242,5.180
3.98866,0.07977,0.47590,5.181
4.01993,0.08040,0.47940,5.189
4.05133,0.08103,0.48292,5.185
4.08224,0.08164,0.48646,5.198
4.11331,0.08227,0.48993,5.200
4.14384,0.08288,0.49339,5.209
4.17482,0.08350,0.49688,5.218
4.20582,0.08412,0.50034,5.224
4.23643,0.08473,0.50381,5.231
4.26693,0.08534,0.50718,5.232
4.29744,0.08595,0.51056,5.218
4.32727,0.08655,0.51397,5.234
4.35728,0.08715,0.51730,5.243
4.38669,0.08773,0.52065,5.246
4.41658,0.08833,0.52399,5.251
4.44632,0.08893,0.52728,5.258
4.47586,0.08952,0.53052,5.261
4.50515,0.09010,0.53377,5.249
4.53416,0.09068,0.53696,5.268
4.56339,0.09127,0.54015,5.272
4.59161,0.09183,0.54324,5.278
4.62026,0.09241,0.54635,5.286
4.64906,0.09298,0.54953,5.288
4.67739,0.09355,0.55266,5.268
4.70563,0.09411,0.55582,5.293
4.73383,0.09468,0.55903,5.296
4.76148,0.09523,0.56214,5.301
4.78934,0.09579,0.56523,5.309
4.81671,0.09633,0.56827,5.319
4.84411,0.09688,0.57124,5.318
4.87149,0.09743,0.57424,5.313
4.89889,0.09798,0.57723,5.319
4.92587,0.09852,0.58019,5.313
4.95304,0.09906,0.58313,5.321
4.98014,0.09960,0.58611,5.330
5.00711,0.10014,0.58904,5.332
5.03340,0.10067,0.59202,5.326
5.05970,0.10119,0.59482,5.337
5.08641,0.10173,0.59769,5.345
5.11233,0.10225,0.60054,5.342
5.13871,0.10277,0.60340,5.340
5.16447,0.10329,0.60621,5.342
5.19058,0.10381,0.60906,5.351
5.21634,0.10433,0.61185,5.348
5.24263,0.10485,0.61468,5.354
5.26831,0.10537,0.61743,5.359
5.29367,0.10587,0.62020,5.365
5.31922,0.10638,0.62297,5.371
5.34487,0.10690,0.62571,5.371
5.36978,0.10740,0.62846,5.363
5.39526,0.10791,0.63118,5.368
5.42027,0.10841,0.63385,5.364
5.44555,0.10891,0.63661,5.373
5.47031,0.10941,0.63935,5.374
5.49566,0.10991,0.64207,5.382
5.52042,0.11041,0.64469,5.382
5.54513,0.11090,0.64730,5.388
5.56978,0.11140,0.64995,5.388
5.59432,0.11189,0.65261,5.391
5.61862,0.11237,0.65521,5.384
5.64323,0.11286,0.65794,5.390
5.66780,0.11336,0.66059,5.398
5.69173,0.11383,0.66318,5.396
5.71607,0.11432,0.66579,5.399
5.74065,0.11481,0.66844,5.410
5.76506,0.11530,0.67100,5.408
5.78972,0.11579,0.67352,5.405
5.81356,0.11627,0.67606,5.404
5.83803,0.11676,0.67861,5.402
5.86217,0.11724,0.68117,5.403
5.88549,0.11771,0.68368,5.408
5.90914,0.11818,0.68627,5.401
5.93311,0.11866,0.68883,5.415
5.95691,0.11914,0.69130,5.426
5.98109,0.11962,0.69378,5.425
6.00520,0.12010,0.69619,5.432
6.02890,0.12058,0.69866,5.421
6.05311,0.12106,0.70116,5.424
6.07663,0.12153,0.70368,5.430
6.10039,0.12201,0.70613,5.429
6.12389,0.12248,0.70864,5.423
6.14716,0.12294,0.71112,5.434
6.17068,0.12341,0.71353,5.430
6.19410,0.12388,0.71600,5.437
6.21721,0.12434,0.71837,5.437
6.24061,0.12481,0.72075,5.440
6.26432,0.12529,0.72311,5.435
6.28774,0.12575,0.72556,5.443
6.31107,0.12622,0.72799,5.434
6.33407,0.12668,0.73042,5.443
6.35766,0.12715,0.73280,5.451
6.38062,0.12761,0.73521,5.447
6.40340,0.12807,0.73753,5.447
6.42687,0.12854,0.73987,5.452
6.45042,0.12901,0.74228,5.449
6.47371,0.12947,0.74470,5.448
6.49699,0.12994,0.74706,5.453
6.52038,0.13041,0.74944,5.451
6.54310,0.13086,0.75189,5.455
6.56656,0.13133,0.75440,5.467
6.58927,0.13179,0.75678,5.463
6.61250,0.13225,0.75917,5.460
6.63607,0.13272,0.76155,5.461
6.65882,0.13318,0.76395,5.456
6.68225,0.13365,0.76634,5.452
6.70579,0.13412,0.76875,5.462
6.72884,0.13458,0.77115,5.464
6.75201,0.13504,0.77359,5.466
6.77567,0.13551,0.77604,5.475
6.79925,0.13599,0.77846,5.471
6.82278,0.13646,0.78091,5.478
6.84599,0.13692,0.78335,5.475
6.86954,0.13739,0.78579,5.468
6.89324,0.13786,0.78817,5.475
6.91621,0.13832,0.79068,5.478
6.93995,0.13880,0.79313,5.473
6.96365,0.13927,0.79561,5.477
6.98695,0.13974,0.79804,5.487
7.01049,0.14021,0.80051,5.480
7.03441,0.14069,0.80296,5.482
7.05846,0.14117,0.80541,5.486
7.08223,0.14164,0.80784,5.486
7.10586,0.14212,0.81035,5.487
7.12996,0.14260,0.81277,5.483
7.15383,0.14308,0.81529,5.488
7.17763,0.14355,0.81780,5.490
7.20160,0.14403,0.82025,5.493
7.22561,0.14451,0.82275,5.499
7.24973,0.14499,0.82523,5.496
7.27364,0.14547,0.82775,5.492
7.29807,0.14596,0.83033,5.497
7.32264,0.14645,0.83278,5.499
7.34690,0.14694,0.83524,5.493
7.37112,0.14742,0.83770,5.501
7.39551,0.14791,0.84022,5.502
7.41983,0.14840,0.84273,5.493
7.44378,0.14888,0.84529,5.511
7.46820,0.14936,0.84778,5.508
7.49279,0.14986,0.85028,5.510
7.51732,0.15035,0.85280,5.515
7.54177,0.15084,0.85534,5.512
7.56706,0.15134,0.85785,5.508
7.59193,0.15184,0.86044,5.508
7.61652,0.15233,0.86296,5.507
7.64131,0.15283,0.86558,5.508
7.66642,0.15333,0.86815,5.507
7.69104,0.15382,0.87074,5.525
7.71644,0.15433,0.87328,5.522
7.74163,0.15483,0.87585,5.520
7.76663,0.15533,0.87844,5.519
7.79187,0.15584,0.88102,5.520
7.81745,0.15635,0.88361,5.512
7.84299,0.15686,0.88621,5.517
7.86820,0.15736,0.88879,5.520
7.89311,0.15786,0.89140,5.520
7.91902,0.15838,0.89401,5.526
7.94412,0.15888,0.89663,5.532
7.96966,0.15939,0.89921,5.526
7.99541,0.15991,0.90181,5.523
8.02097,0.16042,0.90441,5.526
8.04657,0.16093,0.90696,5.523
8.07304,0.16146,0.90957,5.524
8.09913,0.16198,0.91221,5.528
8.12481,0.16250,0.91488,5.531
8.15113,0.16302,0.91752,5.539
8.17696,0.16354,0.92017,5.534
8.20304,0.16406,0.92281,5.536
8.22958,0.16459,0.92540,5.526
8.25577,0.16512,0.92799,5.533
8.28173,0.16563,0.93065,5.525
8.30829,0.16617,0.93329,5.522
8.33498,0.16670,0.93589,5.534
8.36148,0.16723,0.93850,5.531
8.38800,0.16776,0.94110,5.530
8.41456,0.16829,0.94378,5.541
8.44109,0.16882,0.94640,5.535
8.46746,0.16935,0.94914,5.542
8.49418,0.16988,0.95178,5.543
8.52107,0.17042,0.95450,5.546
8.54781,0.17096,0.95709,5.539
8.57489,0.17150,0.95975,5.538
8.60219,0.17204,0.96248,5.539
8.62923,0.17258,0.96516,5.532
8.65611,0.17312,0.96782,5.533
8.68363,0.17367,0.97052,5.532
8.71100,0.17422,0.97316,5.545
8.73801,0.17476,0.97577,5.538
8.76541,0.17531,0.97839,5.544
8.79243,0.17585,0.98102,5.550
8.81987,0.17640,0.98363,5.550
8.84755,0.17695,0.98623,5.543
8.87528,0.17751,0.98875,5.551
8.90305,0.17806,0.99137,5.543
8.93051,0.17861,0.99402,5.549
8.95841,0.17917,0.99662,5.534
8.98558,0.17971,0.99931,5.543
9.01377,0.18028,1.00195,5.547
9.04118,0.18082,1.00462,5.540
9.06919,0.18138,1.00741,5.539
9.09710,0.18194,1.01017,5.550
9.12522,0.18250,1.01301,5.555
9.15318,0.18306,1.01579,5.553
9.18108,0.18362,1.01856,5.549
9.20950,0.18419,1.02134,5.550
9.23754,0.18475,1.02412,5.546
9.26542,0.18531,1.02680,5.548
9.29351,0.18587,1.02964,5.547
9.32139,0.18643,1.03242,5.534
9.34948,0.18699,1.03518,5.551
9.37769,0.18755,1.03794,5.553
9.40588,0.18812,1.04071,5.549
9.43404,0.18868,1.04345,5.558
9.46236,0.18925,1.04623,5.550
9.49035,0.18981,1.04897,5.555
9.51810,0.19036,1.05169,5.550
9.54654,0.19093,1.05444,5.558
9.57468,0.19149,1.05719,5.552
9.60338,0.19207,1.05986,5.555
9.63202,0.19264,1.06257,5.552
9.66030,0.19321,1.06517,5.552
9.68909,0.19378,1.06779,5.546
9.71730,0.19435,1.07047,5.551
9.74580,0.19492,1.07313,5.548
9.77406,0.19548,1.07584,5.557
9.80262,0.19605,1.07860,5.559
9.83059,0.19661,1.08137,5.555
9.85944,0.19719,1.08415,5.557
9.88820,0.19776,1.08689,5.558
9.91647,0.19833,1.08961,5.550
9.94522,0.19890,1.09242,5.555
9.97331,0.19947,1.09523,5.560
10.00201,0.20004,1.09802,5.553
10.03015,0.20060,1.10078,5.561
10.05871,0.20117,1.10350,5.553
10.08665,0.20173,1.10631,5.548
10.11572,0.20231,1.10907,5.553
10.14399,0.20288,1.11183,5.556
10.17301,0.20346,1.11449,5.550
10.20166,0.20403,1.11724,5.548
10.23006,0.20460,1.11991,5.555
10.25849,0.20517,1.12263,5.553
10.28665,0.20573,1.12535,5.551
10.31519,0.20630,1.12802,5.553
10.34345,0.20687,1.13078,5.557
10.37219,0.20744,1.13348,5.559
10.40075,0.20802,1.13627,5.562
10.42972,0.20859,1.13899,5.563
10.45848,0.20917,1.14157,5.560
10.48698,0.20974,1.14425,5.554
10.51575,0.21031,1.14690,5.559
10.54388,0.21088,1.14957,5.555
10.57298,0.21146,1.15223,5.551
10.60115,0.21202,1.15495,5.556
10.62957,0.21259,1.15758,5.543
10.65817,0.21316,1.16037,5.555
10.68735,0.21375,1.16309,5.556
10.71593,0.21432,1.16588,5.553
10.74461,0.21489,1.16870,5.553
10.77309,0.21546,1.17151,5.560
10.80163,0.21603,1.17429,5.561
10.83031,0.21661,1.17704,5.560
10.85870,0.21717,1.17969,5.564
10.88760,0.21775,1.18239,5.558
10.91615,0.21832,1.18511,5.560
10.94537,0.21891,1.18785,5.553
10.97424,0.21948,1.19059,5.551
11.00253,0.22005,1.19330,5.554
11.03118,0.22062,1.19618,5.546
11.05943,0.22119,1.19908,5.548
11.08796,0.22176,1.20195,5.562
11.11618,0.22232,1.20473,5.556
11.14418,0.22288,1.20754,5.554
11.17264,0.22345,1.21029,5.556
11.20130,0.22403,1.21305,5.559
11.22962,0.22459,1.21577,5.548
11.25805,0.22516,1.21845,5.559
11.28656,0.22573,1.22118,5.556
11.31427,0.22629,1.22389,5.547
11.34259,0.22685,1.22655,5.548
11.37096,0.22742,1.22923,5.550
11.39873,0.22797,1.23183,5.549
11.42674,0.22853,1.23439,5.545
11.45460,0.22909,1.23681,5.549
11.48268,0.22965,1.23904,5.546
11.51043,0.23021,1.24111,5.553
11.53851,0.23077,1.24314,5.546
11.56635,0.23133,1.24486,5.547
11.59399,0.23188,1.24632,5.554
11.62176,0.23244,1.24825,5.553
11.64902,0.23298,1.25017,5.553
11.67721,0.23354,1.25213,5.558
11.70511,0.23410,1.25430,5.558
11.73253,0.23465,1.25618,5.553
11.76043,0.23521,1.25820,5.544
11.78778,0.23576,1.26021,5.549
11.81549,0.23631,1.26287,5.540
11.84273,0.23685,1.26567,5.539
11.86998,0.23740,1.26848,5.549
11.89752,0.23795,1.27137,5.548
11.92484,0.23850,1.27418,5.540
11.95224,0.23904,1.27692,5.546
11.97973,0.23959,1.27967,5.555
12.00743,0.24015,1.28233,5.546
12.03416,0.24068,1.28500,5.547
12.06158,0.24123,1.28775,5.559
12.08843,0.24177,1.29035,5.546
12.11489,0.24230,1.29294,5.547
12.14202,0.24284,1.29558,5.543
12.16860,0.24337,1.29837,5.535
12.19565,0.24391,1.30108,5.534
12.22237,0.24445,1.30391,5.532
12.24861,0.24497,1.30673,5.534
12.27511,0.24550,1.30952,5.522
12.30162,0.24603,1.31224,5.538
12.32850,0.24657,1.31492,5.544
12.35463,0.24709,1.31742,5.540
12.38105,0.24762,1.31997,5.538
12.40720,0.24814,1.32250,5.538
12.43306,0.24866,1.32508,5.533
12.45903,0.24918,1.32772,5.529
12.48535,0.24971,1.33046,5.535
12.51121,0.25022,1.33317,5.526
12.53687,0.25074,1.33589,5.529
12.56238,0.25125,1.33870,5.522
12.58823,0.25176,1.34142,5.529
12.61354,0.25227,1.34396,5.534
12.63927,0.25279,1.34652,5.535
12.66549,0.25331,1.34892,5.540
12.69093,0.25382,1.35141,5.534
12.71642,0.25433,1.35393,5.530
12.74221,0.25484,1.35657,5.534
12.76714,0.25534,1.35922,5.531
12.79220,0.25584,1.36198,5.533
12.81720,0.25634,1.36465,5.523
12.84238,0.25685,1.36735,5.523
12.86739,0.25735,1.37002,5.524
12.89236,0.25785,1.37254,5.524
12.91750,0.25835,1.37503,5.529
12.94270,0.25885,1.37753,5.525
12.96768,0.25935,1.38000,5.523
12.99267,0.25985,1.38251,5.519
13.01787,0.26036,1.38511,5.535
13.04240,0.26085,1.38783,5.522
13.06669,0.26133,1.39057,5.517
13.09169,0.26183,1.39320,5.518
13.11636,0.26233,1.39571,5.515
13.14041,0.26281,1.39825,5.522
13.16508,0.26330,1.40067,5.517
13.18957,0.26379,1.40316,5.517
13.21413,0.26428,1.40565,5.521
13.23893,0.26478,1.40816,5.524
13.26349,0.26527,1.41075,5.515
13.28805,0.26576,1.41336,5.512
13.31284,0.26626,1.41609,5.519
13.33705,0.26674,1.41869,5.505
13.36186,0.26724,1.42133,5.517
13.38650,0.26773,1.42385,5.511
13.41086,0.26822,1.42643,5.514
13.43521,0.26870,1.42888,5.511
13.46013,0.26920,1.43142,5.517
13.48466,0.26969,1.43394,5.515
13.50912,0.27018,1.43649,5.504
13.53372,0.27067,1.43909,5.510
13.55800,0.27116,1.44173,5.505
13.58220,0.27164,1.44438,5.509
13.60625,0.27213,1.44692,5.496
13.63080,0.27262,1.44959,5.501
13.65463,0.27309,1.45219,5.501
13.67918,0.27358,1.45479,5.505
13.70341,0.27407,1.45736,5.500
13.72800,0.27456,1.45991,5.509
13.75225,0.27505,1.46240,5.516
13.77704,0.27554,1.46498,5.522
13.80144,0.27603,1.46760,5.511
13.82606,0.27652,1.47026,5.510
13.85039,0.27701,1.47294,5.504
13.87469,0.27749,1.47569,5.502
13.89922,0.27798,1.47835,5.499
13.92341,0.27847,1.48103,5.502
13.94798,0.27896,1.48367,5.500
13.97249,0.27945,1.48635,5.498
13.99669,0.27993,1.48899,5.501
14.02161,0.28043,1.49167,5.503
14.04663,0.28093,1.49429,5.505
14.07110,0.28142,1.49691,5.496
14.09576,0.28192,1.49963,5.504
14.12033,0.28241,1.50235,5.497
14.14491,0.28290,1.50516,5.491
14.16931,0.28339,1.50795,5.505
14.19419,0.28388,1.51065,5.495
14.21914,0.28438,1.51337,5.492
14.24372,0.28487,1.51605,5.493
14.26880,0.28538,1.51877,5.497
14.29350,0.28587,1.52147,5.496
14.31890,0.28638,1.52418,5.498
14.34378,0.28688,1.52693,5.493
14.36867,0.28737,1.52977,5.490
14.39341,0.28787,1.53254,5.482
14.41841,0.28837,1.53532,5.490
14.44297,0.28886,1.53809,5.483
14.46768,0.28935,1.54092,5.488
14.49255,0.28985,1.54364,5.493
14.51728,0.29035,1.54643,5.489
14.54235,0.29085,1.54923,5.493
14.56741,0.29135,1.55202,5.492
14.59254,0.29185,1.55492,5.483
14.61731,0.29235,1.55777,5.482
14.64205,0.29284,1.56059,5.478
14.66732,0.29335,1.56338,5.479
14.69168,0.29383,1.56620,5.486
14.71678,0.29434,1.56901,5.483
14.74162,0.29483,1.57188,5.479
14.76653,0.29533,1.57483,5.478
14.79146,0.29583,1.57781,5.478
14.81688,0.29634,1.58070,5.476
14.84252,0.29685,1.58364,5.473
14.86741,0.29735,1.58652,5.482
14.89228,0.29785,1.58938,5.482
14.91775,0.29836,1.59228,5.480
14.94288,0.29886,1.59524,5.473
14.96809,0.29936,1.59827,5.476
14.99350,0.29987,1.60123,5.461
15.00225,0.30038,1.60426,5.460
15.00524,0.30088,1.60724,5.470
15.00817,0.30139,1.61017,5.468
15.01114,0.30191,1.61315,5.477
15.01416,0.30242,1.61617,5.474
15.01725,0.30293,1.61926,5.468
15.02034,0.30344,1.62235,5.465
15.02343,0.30395,1.62544,5.460
15.02654,0.30446,1.62854,5.464
15.02967,0.30498,1.63167,5.460
15.03273,0.30549,1.63473,5.466
15.03588,0.30601,1.63789,5.464
15.03894,0.30653,1.64094,5.462
15.04223,0.30705,1.64424,5.462
15.04541,0.30758,1.64741,5.468
15.04867,0.30810,1.65068,5.455
15.05185,0.30863,1.65386,5.449
15.05512,0.30915,1.65713,5.449
15.05834,0.30967,1.66035,5.451
15.06154,0.31020,1.66354,5.453
15.06484,0.31072,1.66685,5.466
15.06816,0.31125,1.67017,5.452
15.07148,0.31178,1.67348,5.456
15.07495,0.31232,1.67695,5.453
15.07837,0.31285,1.68038,5.452
15.08174,0.31338,1.68375,5.447
15.08512,0.31392,1.68712,5.442
15.08849,0.31445,1.69050,5.442
15.09194,0.31497,1.69395,5.444
15.09542,0.31551,1.69743,5.448
15.09884,0.31604,1.70085,5.445
15.10239,0.31658,1.70439,5.445
15.10593,0.31713,1.70794,5.437
15.10947,0.31767,1.71147,5.441
15.11299,0.31821,1.71500,5.433
15.11651,0.31875,1.71851,5.431
15.12007,0.31929,1.72208,5.438
15.12367,0.31983,1.72568,5.439
15.12733,0.32037,1.72933,5.440
15.13095,0.32092,1.73296,5.436
15.13468,0.32146,1.73669,5.435
15.13841,0.32201,1.74042,5.425
15.14216,0.32256,1.74416,5.427
15.14593,0.32311,1.74794,5.426
15.14961,0.32365,1.75162,5.420
15.15332,0.32421,1.75532,5.426
15.15716,0.32476,1.75916,5.422
15.16096,0.32530,1.76296,5.424
15.16479,0.32585,1.76679,5.416
15.16862,0.32640,1.77063,5.415
15.17250,0.32696,1.77451,5.416
15.17635,0.32752,1.77836,5.411
15.18023,0.32807,1.78224,5.413
15.18414,0.32863,1.78614,5.414
15.18797,0.32919,1.78998,5.418
15.19190,0.32975,1.79391,5.401